Workbook
Name PVC: [1]자재매입!$AD$7:$AD$11
Name 광신포장: [2]자재매입!#REF!
Name 광신포장: [3]자재매입!#REF!
Name 광신포장: 자재매입!#REF!

Sheet PVC(9410)
G3: 납품실적
C4: 1 | D4: 2 | E4: 3 | F4: 4
A5: 공정 | B5: 차종 | C5: 아이템코드 | D5: 고객품번 | E5: P/NAME | F5: 판매단가 | G5: 1 | H5: 2 | I5: 3 | J5: 4 | K5: 5 | L5: 6 | M5: 7 | N5: 8 | O5: 9 | P5: 10 | Q5: 11 | R5: 12 | S5: 13 | T5: 14 | U5: 15 | V5: 16 | W5: 17 | X5: 18 | Y5: 19 | Z5: 20 | AA5: 21 | AB5: 22 | AC5: 23 | AD5: 24 | AE5: 25 | AF5: 26 | AG5: 27 | AH5: 28 | AI5: 29 | AJ5: 30 | AK5: 31 | AL5: TOTAL | AM5: 매출금액
A6: PVC | B6: PU | C6: G1106-0179 | D6: 822104E000 | E6: PU OUT CHAN LH | F6: 3275 | G6: 720 | H6: 240 | M6: 720 | N6: 300 | P6: 300 | S6: 600 | T6: 720 | U6: 99 | Z6: 720 | AA6: 360 | AB6: 300 | AC6: 300 | AD6: 300 | AG6: 720 | AH6: 300 | AI6: 300 | AJ6: 280 | AL6: =SUM(G6:AK6) -> 7279 | AM6: =F6*AL6 -> 23838725
C7: G1106-0180 | D7: 822204E000 | E7: PU OUT CHAN RH | F7: 3275 | G7: 720 | H7: 240 | M7: 720 | N7: 300 | P7: 300 | S7: 600 | T7: 720 | U7: 95 | Z7: 720 | AA7: 360 | AB7: 300 | AC7: 300 | AD7: 300 | AG7: 720 | AH7: 300 | AI7: 300 | AJ7: 276 | AL7: =SUM(G7:AK7) -> 7271 | AM7: =F7*AL7 -> 23812525
C8: G1102-0620 | D8: 832104E000 | E8: PU(D/CAB) OTR BELT LH | F8: 2592 | G8: 60 | H8: 60 | M8: 60 | T8: 120 | Z8: 120 | AA8: 112 | AG8: 120 | AJ8: -5 | AL8: =SUM(G8:AK8) -> 647 | AM8: =F8*AL8 -> 1677024
C9: G1102-0621 | D9: 832204E000 | E9: PU(D/CAB) OTR BELT RH | F9: 2592 | G9: 60 | H9: 60 | M9: 60 | T9: 120 | Z9: 120 | AA9: 76 | AG9: 120 | AJ9: 4 | AL9: =SUM(G9:AK9) -> 620 | AM9: =F9*AL9 -> 1607040
C10: G1106-0179-01 | D10: 822104E000 | E10: PU Outer Belt FR LH | F10: 3275 | H10: 360 | L10: 480 | U10: 360 | Z10: 600 | AD10: 120 | AJ10: 240 | AL10: =SUM(G10:AK10) -> 2160 | AM10: =F10*AL10 -> 7074000
C11: G1106-0180-01 | D11: 822204E000 | E11: PU Outer Belt FR RH | F11: 3275 | H11: 360 | L11: 480 | U11: 360 | Z11: 600 | AD11: 120 | AJ11: 240 | AL11: =SUM(G11:AK11) -> 2160 | AM11: =F11*AL11 -> 7074000 | AN11: =SUM(AM6:AM13) -> 65083314
C12: G1102-0620-01 | D12: 832104E000 | E12: PU(D/CAB) OTR BELT LH | F12: 2494 | AL12: =SUM(G12:AK12) -> 0 | AM12: =F12*AL12 -> 0
C13: G1102-0621-01 | D13: 832204E000 | E13: PU(D/CAB) OTR BELT RH | F13: 2494 | AL13: =SUM(G13:AK13) -> 0 | AM13: =F13*AL13 -> 0
B14: GV | C14: G1106-0212 | D14: 821707M000 | E14: OTR CHAN LH | F14: 2477 | G14: 180 | P14: 180 | S14: 180 | W14: 180 | AD14: 110 | AL14: =SUM(G14:AK14) -> 830 | AM14: =F14*AL14 -> 2055910
C15: G1106-0213 | D15: 821807M000 | E15: OTR CHAN RH | F15: 2477 | G15: 180 | P15: 180 | S15: 180 | W15: 180 | Z15: 100 | AL15: =SUM(G15:AK15) -> 820 | AM15: =F15*AL15 -> 2031140 | AN15: =SUM(AM14:AM15) -> 4087050
B16: QZ | C16: G1106-0317-00 | D16: 821707P000 | E16: QZ CAR OUT BELT | F16: 2150 | G16: 150 | S16: 150 | Z16: 73 | AD16: 150 | AG16: 150 | AL16: =SUM(G16:AK16) -> 673 | AM16: =F16*AL16 -> 1446950
C17: G1106-0318-00 | D17: 821807P000 | E17: QZ CAR OUT BELT | F17: 1879 | G17: 150 | S17: 150 | Z17: 77 | AD17: 150 | AG17: 150 | AL17: =SUM(G17:AK17) -> 677 | AM17: =F17*AL17 -> 1272083 | AN17: =SUM(AM16:AM17) -> 2719033
B18: TY | C18: G1106-0669-00 | D18: AD66203598-1 | E18: TY Outer Belt FRT LH | F18: 2477 | L18: 70 | AL18: =SUM(G18:AK18) -> 70 | AM18: =F18*AL18 -> 173390
C19: G1106-0670-00 | D19: AD62203598-2 | E19: TY Outer Belt FRT RH | F19: 2477 | L19: 70 | AL19: =SUM(G19:AK19) -> 70 | AM19: =F19*AL19 -> 173390 | AN19: =AM19+AM18 -> 346780
B20: VT | D20: 811515H000 | E20: INR CHAN LH | F20: 2496 | AL20: =SUM(G20:AK20) -> 0 | AM20: =F20*AL20 -> 0
D21: 811615H000 | E21: INR CHAN RH | F21: 2496 | AL21: =SUM(G21:AK21) -> 0 | AM21: =F21*AL21 -> 0
B22: EG | D22: 811517A000 | E22: INR CHAN LH | F22: 1682 | AL22: =SUM(G22:AK22) -> 0 | AM22: =F22*AL22 -> 0
D23: 811617A000 | E23: INR CHAN RH | F23: 1682 | AL23: =SUM(G23:AK23) -> 0 | AM23: =F23*AL23 -> 0
C24: G1106-0009 | D24: 821707A000 | E24: OTR CHAN LH | F24: 2298 | Z24: 92 | AL24: =SUM(G24:AK24) -> 92 | AM24: =F24*AL24 -> 211416
C25: G1106-0010 | D25: 821807A000 | E25: OTR CHAN RH | F25: 2298 | Z25: 156 | AL25: =SUM(G25:AK25) -> 156 | AM25: =F25*AL25 -> 358488 | AN25: =SUM(AM22:AM25) -> 569904
B26: A-1 | D26: 87857-4A100 | E26: TRIM OP'G LH(신) | F26: 1747 | AL26: =SUM(G26:AK26) -> 0 | AM26: =F26*AL26 -> 0
D27: 87867-4A100 | E27: TRIM OP'G RH(신) | F27: 1623 | AL27: =SUM(G27:AK27) -> 0 | AM27: =F27*AL27 -> 0
D28: 87857-4A000 | E28: TRIM OP'G LH(구) | F28: 62 | AL28: =SUM(G28:AK28) -> 0 | AM28: =F28*AL28 -> 0
D29: 87867-4A000 | E29: TRIM OP'G RH(구) | F29: 23 | AL29: =SUM(G29:AK29) -> 0 | AM29: =F29*AL29 -> 0
B30: VT | C30: G1102-0832-01 | D30: 81151-5H000 | E30: VT OUTER BELT 벨트라인 | F30: 3680 | AH30: 3400 | AL30: =SUM(G30:AK30) -> 3400 | AM30: =F30*AL30 -> 12512000 | AN30: =AM30 -> 12512000
B31: EG | E31: EG INR | F31: 3000 | AL31: =SUM(G31:AK31) -> 0 | AM31: =F31*AL31 -> 0
B32: CY | D32: 84248-8C000 | E32: CY 벨드라인( VT INR C/O) | F32: 3546 | AL32: =SUM(G32:AK32) -> 0 | AM32: =F32*AL32 -> 0
B33: DA/LA | D33: P94 581 950 | E33: PROT HEATER | F33: 624 | AL33: =SUM(G33:AK33) -> 0 | AM33: =F33*AL33 -> 0
D34: P94 588 239 | E34: PROT DRYER | F34: 3 | AL34: =SUM(G34:AK34) -> 0 | AM34: =F34*AL34 -> 0
D35: P94 586 275 | E35: CTR PLR OP'G | F35: 3209 | AL35: =SUM(G35:AK35) -> 0 | AM35: =F35*AL35 -> 0
C36: G1117-0024 | D36: P94 586 535 | E36: ROOF RAIL(소) | F36: 1538 | AL36: =SUM(G36:AK36) -> 0 | AM36: =F36*AL36 -> 0
D37: P94 586 532 | E37: ROOF RAIL(대) | F37: 3229 | AL37: =SUM(G37:AK37) -> 0 | AM37: =F37*AL37 -> 0
B38: W-3 | D38: 0K60A 58 810 | E38: OTR CHAN RH | F38: 2760 | AL38: =SUM(G38:AK38) -> 0 | AM38: =F38*AL38 -> 0
D39: 0K60A 59 810 | E39: OTR CHAN LH | F39: 2760 | AL39: =SUM(G39:AK39) -> 0 | AM39: =F39*AL39 -> 0
D40: 0K60N 72 810 | E40: OTR CHAN RH(D/C) | F40: 2384 | AL40: =SUM(G40:AK40) -> 0 | AM40: =F40*AL40 -> 0
D41: 0K60N 73 810 | E41: OTR CHAN LH(D/C) | F41: 2088 | AL41: =SUM(G41:AK41) -> 0 | AM41: =F41*AL41 -> 0
D42: 0K60N 72 820 | E42: INR CHAN RH | F42: 1168 | AL42: =SUM(G42:AK42) -> 0 | AM42: =F42*AL42 -> 0
...

Sheet TPE(9410)
G3: 납품실적
A5: 공정 | B5: 차종 | C5: 화승품번 | D5: 고객품번 | E5: P/NAME | F5: 판매단가 | G5: 1 | H5: 2 | I5: 3 | J5: 4 | K5: 5 | L5: 6 | M5: 7 | N5: 8 | O5: 9 | P5: 10 | Q5: 11 | R5: 12 | S5: 13 | T5: 14 | U5: 15 | V5: 16 | W5: 17 | X5: 18 | Y5: 19 | Z5: 20 | AA5: 21 | AB5: 22 | AC5: 23 | AD5: 24 | AE5: 25 | AF5: 26 | AG5: 27 | AH5: 28 | AI5: 29 | AJ5: 30 | AK5: 31 | AL5: TOTAL | AM5: 매출금액
A6: TPE | B6: HR | C6: G1102-0085 | D6: 825304F000 | E6: G/RUN FRT LH | F6: 2664 | G6: 540 | H6: 300 | I6: 841 | K6: 7 | L6: 360 | M6: 660 | N6: 360 | O6: 300 | P6: 480 | S6: 120 | T6: 360 | U6: 420 | V6: 360 | AA6: 180 | AB6: 300 | AC6: 540 | AD6: 600 | AG6: 120 | AH6: 360 | AI6: 660 | AJ6: 30 | AL6: =SUM(G6:AK6) -> 7898 | AM6: =AL6*F6 -> 21040272
C7: G1102-0128 | D7: 825404F000 | E7: G/RUN FRT RH | F7: 2664 | G7: 540 | H7: 300 | I7: 840 | L7: 360 | M7: 660 | N7: 360 | O7: 300 | P7: 480 | S7: 120 | T7: 360 | U7: 420 | V7: 360 | AA7: 180 | AB7: 300 | AC7: 540 | AD7: 600 | AG7: 120 | AH7: 360 | AI7: 660 | AJ7: 22 | AL7: =SUM(G7:AK7) -> 7882 | AM7: =AL7*F7 -> 20997648
C8: G1102-0181 | D8: 835304F000 | E8: G/RUN RR LH | F8: 2272 | G8: 160 | H8: 60 | I8: 80 | L8: 80 | N8: 80 | P8: 80 | T8: 80 | U8: 80 | V8: 80 | AA8: 80 | AE8: 7 | AG8: 80 | AH8: 80 | AL8: =SUM(G8:AK8) -> 1027 | AM8: =AL8*F8 -> 2333344
C9: G1102-0218 | D9: 835404F000 | E9: G/RUN RR RH | F9: 2272 | G9: 160 | H9: 60 | I9: 80 | L9: 80 | N9: 80 | P9: 80 | T9: 80 | U9: 80 | V9: 80 | AA9: 80 | AE9: 11 | AG9: 80 | AH9: 80 | AL9: =SUM(G9:AK9) -> 1031 | AM9: =AL9*F9 -> 2342432 | AN9: =SUM(AM6:AM9) -> 46713696
B10: JB | C10: G1102-0727 | D10: 82530-1G000 | E10: G/RUN FRT LH | F10: 2735 | AL10: =SUM(G10:AK10) -> 0 | AM10: =AL10*F10 -> 0
C11: G1102-0728 | D11: 82540-1G000 | E11: G/RUN FRT RH | F11: 2735 | AL11: =SUM(G11:AK11) -> 0 | AM11: =AL11*F11 -> 0
C12: G1102-0729 | D12: 83531-1G000 | E12: G/RUN RR LH(4DR) | F12: 4148 | AL12: =SUM(G12:AK12) -> 0 | AM12: =AL12*F12 -> 0
C13: G1102-0730 | D13: 83541-1G000 | E13: G/RUN RR RH(4DR) | F13: 4136 | AL13: =SUM(G13:AK13) -> 0 | AM13: =AL13*F13 -> 0
C14: G1102-0762 | D14: 83531-1G200 | E14: G/RUN RR LH(5DR) | F14: 4136 | AL14: =SUM(G14:AK14) -> 0 | AM14: =AL14*F14 -> 0
C15: G1102-0763 | D15: 83541-1G200 | E15: G/RUN RR RH(5DR) | F15: 4146 | AL15: =SUM(G15:AK15) -> 0 | AM15: =AL15*F15 -> 0 | AN15: =SUM(AM10:AM15) -> 0
B16: JA | C16: G1102-1361-00 | D16: 82530G6000 | E16: JA GLASS RUN FRT LH | F16: 2558 | G16: 480 | H16: 480 | I16: 427 | L16: 420 | M16: 420 | O16: 540 | P16: 540 | S16: 540 | T16: 420 | U16: 540 | V16: 540 | W16: 540 | Z16: 360 | AA16: 420 | AB16: 540 | AC16: 540 | AD16: 540 | AG16: 420 | AH16: 540 | AI16: 540 | AJ16: 420 | AK16: 28 | AL16: =SUM(G16:AK16) -> 10235 | AM16: =AL16*F16 -> 26181130
C17: G1102-1362-00 | D17: 82540G6000 | E17: JA GLASS RUN FRT RH | F17: 2558 | G17: 480 | H17: 480 | I17: 427 | K17: 8 | L17: 420 | M17: 420 | O17: 540 | P17: 540 | S17: 540 | T17: 420 | U17: 540 | V17: 540 | W17: 540 | Z17: 360 | AA17: 420 | AB17: 540 | AC17: 540 | AD17: 540 | AG17: 420 | AH17: 540 | AI17: 540 | AJ17: 420 | AK17: 10 | AL17: =SUM(G17:AK17) -> 10225 | AM17: =AL17*F17 -> 26155550
C18: R1102-1363-00 | D18: 83530G6000 | E18: JA GLASS RUN RR LH | F18: 3443 | G18: 400 | H18: 400 | I18: 600 | L18: 600 | M18: 400 | O18: 400 | P18: 400 | S18: 400 | T18: 600 | U18: 400 | V18: 400 | W18: 400 | Z18: 600 | AA18: 600 | AB18: 400 | AC18: 400 | AD18: 400 | AG18: 600 | AH18: 400 | AI18: 400 | AJ18: 600 | AL18: =SUM(G18:AK18) -> 9800 | AM18: =AL18*F18 -> 33741400
C19: R1102-1364-00 | D19: 83540G6000 | E19: JA GLASS RUN RR RH | F19: 3443 | G19: 400 | H19: 400 | I19: 600 | L19: 600 | M19: 400 | O19: 400 | P19: 400 | S19: 400 | T19: 600 | U19: 400 | V19: 400 | W19: 400 | Z19: 600 | AA19: 600 | AB19: 400 | AC19: 400 | AD19: 400 | AG19: 600 | AH19: 400 | AI19: 400 | AJ19: 600 | AL19: =SUM(G19:AK19) -> 9800 | AM19: =AL19*F19 -> 33741400
C20: G1102-1363-01 | D20: 83530G6000 | E20: JA Glass run RR LH | F20: 3478 | AE20: 29 | AL20: =SUM(G20:AK20) -> 29 | AM20: =AL20*F20 -> 100862
C21: G1102-1364-01 | D21: 83540G6000 | E21: JA Glass run RR RH | F21: 3478 | AE21: 30 | AL21: =SUM(G21:AK21) -> 30 | AM21: =AL21*F21 -> 104340 | AN21: =SUM(AM16:AM21) -> 120024682
B22: BL | C22: 11020865 | D22: 82516-3E000 | E22: G/RUN FRT LH | F22: 4249 | AL22: =SUM(G22:AK22) -> 0 | AM22: =AL22*F22 -> 0
C23: 11020872 | D23: 82526-3E000 | E23: G/RUN FRT RH | F23: 4249 | AL23: =SUM(G23:AK23) -> 0 | AM23: =AL23*F23 -> 0
C24: 11020866 | D24: 83530-3E000 | E24: G/RUN RR LH | F24: 3037 | AL24: =SUM(G24:AK24) -> 0 | AM24: =AL24*F24 -> 0
C25: 11020871 | D25: 83540-3E000 | E25: G/RUN RR RH | F25: 3037 | AL25: =SUM(G25:AK25) -> 0 | AM25: =AL25*F25 -> 0 | AN25: =SUM(AM22:AM25) -> 0
B26: M2JO | C26: G1102-1487-03 | D26: 42574263 | E26: M2JO Glass run FR RH | F26: 4059 | AK26: 50 | AL26: =SUM(G26:AK26) -> 50 | AM26: =AL26*F26 -> 202950 | AN26: =AM26 -> 202950
C27: G1102-1489-02 | D27: 42574265 | E27: M2JO GLASS RUN RR RH | F27: 5335 | AL27: =SUM(G27:AK27) -> 0 | AM27: =AL27*F27 -> 0
B28: CE1 | C28: G1125-0076-00 | D28: 831A0KL000 | E28: CE1 P/SEAL RR LH | F28: 1649 | L28: 101 | N28: 200 | S28: 40 | W28: 200 | Z28: 360 | AK28: 20 | AL28: =SUM(G28:AK28) -> 921 | AM28: =AL28*F28 -> 1518729
C29: G1125-0077-00 | D29: 831B0KL000 | E29: CE1 P/SEAL RR RH | F29: 1649 | L29: 74 | N29: 200 | S29: 400 | W29: 200 | Z29: 25 | AL29: =SUM(G29:AK29) -> 899 | AM29: =AL29*F29 -> 1482451 | AN29: =AM29+AM28 -> 3001180
B30: 2M400 | C30: G1102-1486-03 | D30: 42574262 | E30: M2JO Glass run FR LH | F30: 4059 | AL30: =SUM(G30:AK30) -> 0 | AM30: =AL30*F30 -> 0
C31: G1102-1486-04 | D31: 42574262 | E31: M2JO Glass run FR LH | F31: 4059 | AL31: =SUM(G31:AK31) -> 0 | AM31: =AL31*F31 -> 0
C32: G1102-1487-02 | D32: 42574263 | E32: M2JO Glass run FR RH | F32: 4059 | AL32: =SUM(G32:AK32) -> 0 | AM32: =AL32*F32 -> 0
C33: G1102-1487-03 | D33: 42574263 | E33: M2JO Glass run FR RH | F33: 4059 | AE33: 50 | AL33: =SUM(G33:AK33) -> 50 | AM33: =AL33*F33 -> 202950
C34: G1102-1490-02 | D34: 42574266 | E34: M2JC Glass run RR LH | F34: 5335 | AL34: =SUM(G34:AK34) -> 0 | AM34: =AL34*F34 -> 0
C35: G1102-1489-02 | D35: 42574265 | E35: M2JO Glass run RR RH | F35: 5335 | AL35: =SUM(G35:AK35) -> 0 | AM35: =AL35*F35 -> 0
C36: G1102-1491-02 | D36: 42574267 | E36: M2JC Glass run RR RH | F36: 3463 | AL36: =SUM(G36:AK36) -> 0 | AM36: =AL36*F36 -> 0
C37: G1102-1491-03 | D37: 42574267 | E37: M2JC Glass run RR RH | F37: 3463 | AL37: =SUM(G37:AK37) -> 0 | AM37: =AL37*F37 -> 0
B38: OV1K 조영->아성화승납품 | C38: G1110-0202-00 | D38: 86430X9000 | E38: OV1k Hood Seal | F38: 1076 | G38: 480 | H38: 400 | I38: 320 | J38: 240 | L38: 400 | M38: 320 | N38: 400 | O38: 240 | P38: 320 | S38: 560 | Z38: 1648 | AC38: 432 | AD38: 576 | AG38: 432 | AK38: 1296 | AL38: =SUM(G38:AK38) -> 8064 | AM38: =AL38*F38 -> 8676864
C39: G1110-0203-00 | D39: 86435X9000 | E39: OV1k Hood Seal (FRUNK) | F39: 1712 | G39: 480 | H39: 400 | I39: 320 | J39: 240 | L39: 400 | M39: 320 | N39: 400 | O39: 240 | P39: 320 | S39: 560 | Z39: 1648 | AC39: 432 | AD39: 576 | AG39: 432 | AK39: 1296 | AL39: =SUM(G39:AK39) -> 8064 | AM39: =AL39*F39 -> 13805568
C40: G1160-0009-00 | D40: 81855X9100 | E40: OV1k Power Tail Gate Side Strip LH | F40: 1661 | H40: 576 | I40: 288 | L40: 432 | M40: 432 | O40: 432 | P40: 432 | S40: 432 | Z40: 2503 | AB40: 320 | AC40: 80 | AD40: 480 | AG40: 240 | AK40: 720 | AL40: =SUM(G40:AK40) -> 7367 | AM40: =AL40*F40 -> 12236587
C41: G1160-0010-00 | D41: 81865X9100 | E41: OV1k Power Tail Gate Side Strip RH | F41: 1661 | H41: 576 | I41: 288 | L41: 432 | M41: 432 | O41: 432 | P41: 432 | S41: 432 | Z41: 2508 | AB41: 320 | AC41: 80 | AD41: 480 | AG41: 240 | AK41: 720 | AL41: =SUM(G41:AK41) -> 7372 | AM41: =AL41*F41 -> 12244892 | AN41: =SUM(AM38:AM41) -> 46963911
B42: 9BQC 말일 화승납품 마감하기 | C42: G1102-2752-00 | D42: 42933952 | E42: 9BQC FRT LH | F42: 2858 | G42: 1300 | H42: 600 | I42: 1400 | J42: 600 | L42: 1200 | M42: 900 | N42: 1000 | O42: 1000 | P42: 900 | S42: 1200 | T42: 900 | U42: 900 | V42: 1200 | Z42: 600 | AA42: 1000 | AB42: 900 | AC42: 900 | AD42: 900 | AG42: 1000 | AH42: 600 | AI42: 1000 | AJ42: 1000 | AK42: 400 | AL42: =SUM(G42:AK42) -> 21400 | AM42: =AL42*F42 -> 61161200
C43: G1102-2753-00 | D43: 42933953 | E43: 9BQC FRT RH | F43: 2858 | G43: 1300 | H43: 600 | I43: 1400 | J43: 600 | L43: 1200 | M43: 900 | N43: 1000 | O43: 1000 | P43: 900 | S43: 1200 | T43: 900 | U43: 900 | V43: 1200 | Z43: 600 | AA43: 1000 | AB43: 900 | AC43: 900 | AD43: 700 | AG43: 1000 | AH43: 600 | AI43: 1000 | AJ43: 1000 | AK43: 400 | AL43: =SUM(G43:AK43) -> 21200 | AM43: =AL43*F43 -> 60589600
...

Sheet OWF10(상품)
G3: 납품실적
A5: 공정 | B5: 차종 | C5: 화승품번 | D5: 고객품번 | E5: P/NAME | F5: 판매단가 | G5: 1 | H5: 2 | I5: 3 | J5: 4 | K5: 5 | L5: 6 | M5: 7 | N5: 8 | O5: 9 | P5: 10 | Q5: 11 | R5: 12 | S5: 13 | T5: 14 | U5: 15 | V5: 16 | W5: 17 | X5: 18 | Y5: 19 | Z5: 20 | AA5: 21 | AB5: 22 | AC5: 23 | AD5: 24 | AE5: 25 | AF5: 26 | AG5: 27 | AH5: 28 | AI5: 29 | AJ5: 30 | AK5: 31 | AL5: TOTAL | AM5: 매출금액
B6: DL3A | C6: F1102-2028-01 | D6: R1102-2028 | E6: FRT LH(4단) | F6: 4520 | AL6: =SUM(G6:AK6) -> 0 | AM6: =AL6*F6 -> 0
C7: F1102-2029-01 | D7: R1102-2029 | E7: FRT RH(4단) | F7: 4520 | AL7: =SUM(G7:AK7) -> 0 | AM7: =AL7*F7 -> 0 | AN7: =AM6+AM7 -> 0
A8: 다솜 | B8: JK 1 | C8: G1129-0062-00 | D8: 831C0-AR000 | E8: JK Wheel Seal RR LH | F8: 1546 | G8: 600 | I8: 600 | L8: 500 | M8: 300 | N8: 200 | O8: 500 | P8: 400 | S8: 600 | T8: 300 | V8: 300 | W8: 10 | AG8: 970 | AL8: =SUM(G8:AK8) -> 5280 | AM8: =AL8*F8 -> 8162880 | AN8: =SUM(AM8:AM11) -> 20237140
C9: G1129-0063-00 | D9: 831D0-AR000 | E9: JK Wheel Seal RR RH | F9: 1546 | G9: 600 | I9: 600 | L9: 500 | M9: 300 | N9: 200 | O9: 500 | P9: 200 | S9: 600 | T9: 300 | V9: 300 | W9: 200 | AG9: 1100 | AH9: 10 | AL9: =SUM(G9:AK9) -> 5410 | AM9: =AL9*F9 -> 8363860
C10: G1129-0062-01 | D10: 831C0-AR000 | E10: JK Wheel Seal RR LH(22라인) | F10: 1546 | L10: 82 | Z10: 1118 | AL10: =SUM(G10:AK10) -> 1200 | AM10: =AL10*F10 -> 1855200
C11: G1129-0063-01 | D11: 831D0-AR000 | E11: JK Wheel Seal RR RH(22라인) | F11: 1546 | L11: 230 | Z11: 970 | AL11: =SUM(G11:AK11) -> 1200 | AM11: =AL11*F11 -> 1855200
A12: 임가공 | B12: JK 1 | C12: F1129-0062-00 | D12: 831C0-AR000 | E12: JK Wheel Seal RR LH | F12: 1490 | AK12: 1690 | AL12: =SUM(G12:AK12) -> 1690 | AM12: =AL12*F12 -> 2518100
C13: F1129-0063-00 | D13: 831D0-AR000 | E13: JK Wheel Seal RR RH | F13: 1490 | AK13: 1690 | AL13: =SUM(G13:AK13) -> 1690 | AM13: =AL13*F13 -> 2518100
B14: PD | C14: G1102-1346-00 | D14: 82530-G3000 | E14: FRT LH | F14: 5333 | AE14: 2 | AL14: =SUM(G14:AK14) -> 2 | AM14: =AL14*F14 -> 10666
C15: G1102-1347-00 | D15: 82540-G3000 | E15: FRT RH | F15: 1258 | AL15: =SUM(G15:AK15) -> 0 | AM15: =AL15*F15 -> 0
C16: G1108-1348-00 | D16: 83530-3G000 | E16: RR LH | F16: 1773 | AL16: =SUM(G16:AK16) -> 0 | AM16: =AL16*F16 -> 0
C17: G1102-1350-00 | D17: 83540-G3000 | E17: RR RH | F17: 1773 | AL17: =SUM(G17:AK17) -> 0 | AM17: =AL17*F17 -> 0 | AN17: =SUM(AM14:AM17) -> 10666
A18: 다솜 | B18: NX 4 | C18: G1102-1973-00 | D18: 82530-9N000 | E18: FRT LH | F18: 5322 | G18: 1680 | H18: 960 | I18: 480 | L18: 480 | M18: 1200 | N18: 960 | O18: 720 | P18: 720 | T18: 1200 | U18: 241 | V18: 506 | AC18: 1200 | AD18: 480 | AG18: 1440 | AI18: 960 | AK18: 12 | AL18: =SUM(G18:AK18) -> 13239 | AM18: =AL18*F18 -> 70457958
C19: G1102-1974-00 | D19: 82540-9N000 | E19: FRT RH | F19: 5322 | G19: 1680 | H19: 960 | I19: 480 | L19: 480 | M19: 1200 | N19: 960 | O19: 720 | P19: 513 | T19: 1200 | U19: 241 | V19: 720 | AC19: 1200 | AD19: 480 | AE19: 5 | AG19: 1440 | AI19: 960 | AL19: =SUM(G19:AK19) -> 13239 | AM19: =SUM(AL19*F19) -> 70457958
C20: G1102-1973-01 | D20: 82530-9N000 | E20: NX4 Glass run FR LH 현대CKD | F20: 5322 | L20: 480 | P20: 241 | AI20: 420 | AL20: =SUM(G20:AK20) -> 1141 | AM20: =AL20*F20 -> 6072402
C21: G1102-1974-01 | D21: 82540-9N000 | E21: NX4 Glass run FR RH 현대CKD | F21: 5322 | L21: 480 | V21: 241 | AI21: 420 | AL21: =SUM(G21:AK21) -> 1141 | AM21: =SUM(AL21*F21) -> 6072402 | AN21: =SUM(AM18:AM21) -> 153060720
B22: NX 4 a | C22: G1102-2069-01 | D22: 82530-CW000 | E22: FRT LH | F22: 5800 | W22: 5760 | AH22: 5760 | AJ22: 1440 | AL22: =SUM(G22:AK22) -> 12960 | AM22: =AL22*F22 -> 75168000
C23: G1102-2070-01 | D23: 8250-CW000 | E23: FRT RH | F23: 5800 | W23: 5760 | AH23: 5760 | AJ23: 1440 | AL23: =SUM(G23:AK23) -> 12960 | AM23: =SUM(AL23*F23) -> 75168000 | AN23: =SUM(AM22:AM23) -> 150336000
B24: NX 4 M | C24: G1102-2069-02 | D24: 82530-CW000 | E24: FRT LH | F24: 1597 | AL24: =SUM(G24:AK24) -> 0 | AM24: =AL24*F24 -> 0
C25: G1102-2070-02 | D25: 8250-CW000 | E25: FRT RH | F25: 1597 | AL25: =SUM(G25:AK25) -> 0 | AM25: =SUM(AL25*F25) -> 0 | AN25: =SUM(AM24:AM25) -> 0
B26: DS | C26: G1103-2081-01 | D26: 55112362AI | E26: DS(CREW) Door Side RR RH | F26: 5845 | H26: 1920 | I26: 1280 | L26: 1600 | O26: 1280 | S26: 1280 | T26: 1280 | V26: 1280 | W26: 320 | Z26: 320 | AB26: 960 | AC26: 640 | AD26: 640 | AE26: 640 | AG26: 1280 | AI26: 1280 | AK26: 1280 | AL26: =SUM(G26:AK26) -> 17280 | AM26: =SUM(AL26*F26) -> 101001600
C27: G1103-2082-01 | D27: 55112363AI | E27: DS(CREW) Door Side RR LH | F27: 5845 | H27: 1280 | I27: 960 | L27: 1600 | O27: 1280 | P27: 640 | S27: 1280 | T27: 1280 | V27: 1280 | Z27: 320 | AB27: 2240 | AC27: 640 | AD27: 640 | AE27: 640 | AG27: 1280 | AI27: 640 | AJ27: 960 | AK27: 1920 | AL27: =SUM(G27:AK27) -> 18880 | AM27: =SUM(AL27*F27) -> 110353600
C28: G1103-1562-00 | D28: 55112362AH | E28: DS(CREW) Door Side RR RH(미) | F28: 5791 | AL28: =SUM(G28:AK28) -> 0 | AM28: =SUM(AL28*F28) -> 0
C29: G1103-1563-03 | D29: 55112363AH | E29: DS(CREW) Door Side RR LH(미) | F29: 5845 | AL29: =SUM(G29:AK29) -> 0 | AM29: =SUM(AL29*F29) -> 0
C30: G1103-1499-00 | D30: 55112374AH | E30: DS(QUAD) Door Side RR RH (설변) | F30: 5905 | AL30: =SUM(G30:AK30) -> 0 | AM30: =SUM(AL30*F30) -> 0
C31: G1103-1504-00 | D31: 55112375AH | E31: DS(QUAD) Door Side RR LH (설변) | F31: 5905 | AL31: =SUM(G31:AK31) -> 0 | AM31: =SUM(AL31*F31) -> 0
C32: G1103-2085-00 | D32: 68563582AC | E32: DS(TRUCK) Door Side FR RH | F32: 5694 | I32: 280 | V32: 560 | AG32: 280 | AL32: =SUM(G32:AK32) -> 1120 | AM32: =SUM(AL32*F32) -> 6377280
C33: G1103-2086-00 | D33: 68563583AC | E33: DS(TRUCK) Door Side FR LH | F33: 6154 | I33: 280 | V33: 560 | AG33: 280 | AL33: =SUM(G33:AK33) -> 1120 | AM33: =SUM(AL33*F33) -> 6892480 | AN33: =SUM(AM26:AM33) -> 224624960
B34: DT | C34: G1103-1506-00 | D34: 68291620AD | E34: DT(CREW) Door Side RR RH | F34: 5841 | AL34: =SUM(G34:AK34) -> 0 | AM34: =SUM(AL34*F34) -> 0
C35: G1103-1507-00 | D35: 68291621AD | E35: DT(CREW) Door Side RR LH | F35: 5841 | AL35: =SUM(G35:AK35) -> 0 | AM35: =SUM(AL35*F35) -> 0
C36: G1103-2137-01 | D36: 68291620AD | E36: DT(CREW) Door Side RR RH (CREW) | F36: 6206 | I36: 6480 | P36: 6120 | U36: 720 | Z36: 6480 | AD36: 6480 | AK36: 6120 | AL36: =SUM(G36:AK36) -> 32400 | AM36: =SUM(AL36*F36) -> 201074400
C37: G1103-2138-01 | D37: 68291621AD | E37: DT(CREW) Door Side RR LH (CREW) | F37: 6206 | I37: 6480 | P37: 6120 | U37: 720 | Z37: 6480 | AD37: 6480 | AK37: 6120 | AL37: =SUM(G37:AK37) -> 32400 | AM37: =SUM(AL37*F37) -> 201074400 | AN37: =SUM(AM34:AM37) -> 402148800 | AP37: =AN45+AN39+AN33+AN23 -> 842038080
C38: G1103-2139-01 | D38: 68291618AD | E38: DT(QUAD) Door Side RR RH | F38: 6216 | P38: 360 | AK38: 360 | AL38: =SUM(G38:AK38) -> 720 | AM38: =SUM(AL38*F38) -> 4475520
C39: G1103-2140-01 | D39: 68291619AD | E39: DT(QUAD) Door Side RR LH | F39: 6216 | P39: 360 | AK39: 360 | AL39: =SUM(G39:AK39) -> 720 | AM39: =SUM(AL39*F39) -> 4475520 | AN39: =SUM(AM34:AM39) -> 411099840
B40: ME1a | C40: G1125-0083-01 | D40: 831B0TD000 | E40: ME1a Center Pillar Seal RR RH | F40: 1283 | AL40: =SUM(G40:AK40) -> 0 | AM40: =SUM(AL40*F40) -> 0
C41: G1125-0082-01 | D41: 831A0TD000 | E41: ME1a Center Pillar Seal RR LH | F41: 1283 | AL41: =SUM(G41:AK41) -> 0 | AM41: =SUM(AL41*F41) -> 0
B42: NE1a | C42: G1103-1871-02 | D42: 82130PI000 | E42: NE1a Door Side FR LH | F42: 4379 | H42: 320 | N42: 320 | Q42: 320 | V42: 320 | AC42: 640 | AD42: 320 | AI42: 320 | AJ42: 320 | AL42: =SUM(G42:AK42) -> 2880 | AM42: =SUM(AL42*F42) -> 12611520
C43: G1103-1872-02 | D43: 82140PI000 | E43: NE1a Door Side FR RH | F43: 4379 | H43: 320 | N43: 320 | Q43: 320 | V43: 320 | AC43: 640 | AD43: 320 | AI43: 320 | AJ43: 320 | AK43: 320 | AL43: =SUM(G43:AK43) -> 3200 | AM43: =SUM(AL43*F43) -> 14012800
...

Sheet OWF101
F3: 납품실적
A5: 공정 | B5: 차종 | C5: 고객품번 | D5: P/NAME | E5: 판매단가 | F5: 1 | G5: 2 | H5: 3 | I5: 4 | J5: 5 | K5: 6 | L5: 7 | M5: 8 | N5: 9 | O5: 10 | P5: 11 | Q5: 12 | R5: 13 | S5: 14 | T5: 15 | U5: 16 | V5: 17 | W5: 18 | X5: 19 | Y5: 20 | Z5: 21 | AA5: 22 | AB5: 23 | AC5: 24 | AD5: 25 | AE5: 26 | AF5: 27 | AG5: 28 | AH5: 29 | AI5: 30 | AJ5: 31 | AK5: TOTAL | AL5: 매출금액
A6: EPDM | B6: M200 | C6: P96 601 512 | D6: FRT LH | E6: 539 | AK6: =SUM(F6:AJ6) -> 0 | AL6: =E6*AK6 -> 0
C7: P96 601 513 | D7: FRT RH | E7: 539 | AK7: =SUM(F7:AJ7) -> 0 | AL7: =E7*AK7 -> 0
C8: P96 601 514 | D8: RR LH | E8: 541 | AK8: =SUM(F8:AJ8) -> 0 | AL8: =E8*AK8 -> 0
C9: P96 601 515 | D9: RR RH | E9: 562 | AK9: =SUM(F9:AJ9) -> 0 | AL9: =E9*AK9 -> 0 | AM9: =SUM(AL6:AL9) -> 0
B10: M300 KD | C10: 95215384 | D10: FRT LH | E10: 747 | AK10: =SUM(F10:AJ10) -> 0 | AL10: =E10*AK10 -> 0
C11: 95215385 | D11: FRT RH | E11: 747 | AK11: =SUM(F11:AJ11) -> 0 | AL11: =E11*AK11 -> 0
C12: 95971339 | D12: RR LH | E12: 706 | AK12: =SUM(F12:AJ12) -> 0 | AL12: =E12*AK12 -> 0
C13: 95971340 | D13: RR RH | E13: 706 | AK13: =SUM(F13:AJ13) -> 0 | AL13: =E13*AK13 -> 0 | AM13: =SUM(AL10:AL13) -> 0
B14: M300 F | C14: 95297763 | D14: FRT LH | E14: 863 | AK14: =SUM(F14:AJ14) -> 0 | AL14: =E14*AK14 -> 0
C15: 95297764 | D15: FRT RH | E15: 863 | AK15: =SUM(F15:AJ15) -> 0 | AL15: =E15*AK15 -> 0
C16: 42348903 | D16: RR LH(신) | E16: 831 | AK16: =SUM(F16:AJ16) -> 0 | AL16: =E16*AK16 -> 0
C17: 42348904 | D17: RR RH(신) | E17: 831 | AK17: =SUM(F17:AJ17) -> 0 | AL17: =E17*AK17 -> 0
C18: 9515 7180 | D18: RR LH(구) | E18: 831 | AK18: =SUM(F18:AJ18) -> 0 | AL18: =E18*AK18 -> 0
C19: 9515 7181 | D19: RR RH(구) | E19: 831 | AK19: =SUM(F19:AJ19) -> 0 | AL19: =E19*AK19 -> 0 | AM19: =SUM(AL14:AL19) -> 0
B20: M300 MCE | C20: 95319954 | D20: FRT LH | E20: 749 | AK20: =SUM(F20:AJ20) -> 0 | AL20: =E20*AK20 -> 0
C21: 95319955 | D21: FRT RH | E21: 708 | AK21: =SUM(F21:AJ21) -> 0 | AL21: =E21*AK21 -> 0
C22: 42348901 | D22: RR LH | E22: 668 | AK22: =SUM(F22:AJ22) -> 0 | AL22: =E22*AK22 -> 0
C23: 42348902 | D23: RR RH | E23: 668 | AK23: =SUM(F23:AJ23) -> 0 | AL23: =E23*AK23 -> 0 | AM23: =SUM(AL20:AL23) -> 0
AK24: =SUM(AK6:AK23) -> 0 | AL24: =SUM(AL6:AL23) -> 0

Sheet TNC(tncol)
F3: 납품실적
A5: 공정 | B5: 차종 | C5: 고객품번 | D5: P/NAME | E5: 판매단가 | F5: 1 | G5: 2 | H5: 3 | I5: 4 | J5: 5 | K5: 6 | L5: 7 | M5: 8 | N5: 9 | O5: 10 | P5: 11 | Q5: 12 | R5: 13 | S5: 14 | T5: 15 | U5: 16 | V5: 17 | W5: 18 | X5: 19 | Y5: 20 | Z5: 21 | AA5: 22 | AB5: 23 | AC5: 24 | AD5: 25 | AE5: 26 | AF5: 27 | AG5: 28 | AH5: 29 | AI5: 30 | AJ5: 31 | AK5: TOTAL | AL5: 매출금액
A6: TNCOL | B6: XM | C6: 82530-2P000 | D6: FRT LH | E6: 2629 | AK6: =SUM(F6:AJ6) -> 0 | AL6: =E6*AK6 -> 0
C7: 82540-2P000 | D7: FRT RH | E7: 2629 | AK7: =SUM(F7:AJ7) -> 0 | AL7: =E7*AK7 -> 0
C8: 83530-2P000 | D8: RR LH | E8: 2756 | AK8: =SUM(F8:AJ8) -> 0 | AL8: =E8*AK8 -> 0
C9: 83540-2P000 | D9: RR RH | E9: 2756 | AK9: =SUM(F9:AJ9) -> 0 | AL9: =E9*AK9 -> 0 | AM9: =SUM(AL6:AL9) -> 0
B10: H45 | C10: 803310407R | D10: FRT LH | E10: 4980 | AK10: =SUM(F10:AJ10) -> 0 | AL10: =E10*AK10 -> 0
C11: 803300148R | D11: FRT RH | E11: 5021 | AK11: =SUM(F11:AJ11) -> 0 | AL11: =E11*AK11 -> 0
C12: G1102-1174-00 | D12: RR LH | E12: 4356 | AK12: =SUM(F12:AJ12) -> 0 | AL12: =E12*AK12 -> 0
C13: 823307754R | D13: RR RH | E13: 4337 | AK13: =SUM(F13:AJ13) -> 0 | AL13: =E13*AK13 -> 0 | AM13: =SUM(AL10:AL13) -> 0
B14: HI | C14: 82231-D2000 | D14: FRT LH | E14: 2615 | AJ14: 12 | AK14: =SUM(F14:AJ14) -> 12 | AL14: =E14*AK14 -> 31380
C15: 82241-D2000 | D15: FRT RH | E15: 2615 | AK15: =SUM(F15:AJ15) -> 0 | AL15: =E15*AK15 -> 0
C16: 83231-D2000 | D16: RR LH | E16: 4053 | AJ16: 1 | AK16: =SUM(F16:AJ16) -> 1 | AL16: =E16*AK16 -> 4053
C17: 83241-D2000 | D17: RR RH | E17: 4053 | AK17: =SUM(F17:AJ17) -> 0 | AL17: =E17*AK17 -> 0
C18: 83231-D2500 | D18: RR LH | E18: 3887 | AK18: =SUM(F18:AJ18) -> 0 | AL18: =E18*AK18 -> 0
C19: 83241-D2500 | D19: RR RH | E19: 3863 | AK19: =SUM(F19:AJ19) -> 0 | AL19: =E19*AK19 -> 0 | AM19: =SUM(AL14:AL19) -> 35433
B20: VI | C20: 82231-3N000 | D20: FRT LH | E20: 1469 | AK20: =SUM(F20:AJ20) -> 0 | AL20: =E20*AK20 -> 0
C21: 82241-3N000 | D21: FRT RH | E21: 1531 | AJ21: 6 | AK21: =SUM(F21:AJ21) -> 6 | AL21: =E21*AK21 -> 9186
C22: 83231-3N000 | D22: RR LH | E22: 1655 | AK22: =SUM(F22:AJ22) -> 0 | AL22: =E22*AK22 -> 0
C23: 83241-3N000 | D23: RR RH | E23: 1662 | AJ23: 5 | AK23: =SUM(F23:AJ23) -> 5 | AL23: =E23*AK23 -> 8310
C24: 83231-3N500 | D24: RR LH | E24: 1679 | AK24: =SUM(F24:AJ24) -> 0 | AL24: =E24*AK24 -> 0
C25: 83241-3N500 | D25: RR RH | E25: 1679 | AK25: =SUM(F25:AJ25) -> 0 | AL25: =E25*AK25 -> 0 | AM25: =SUM(AL20:AL25) -> 17496
AK26: =SUM(AK6:AK25) -> 24 | AL26: =SUM(AL6:AL25) -> 52929
AB28: 0월 마감금액 | AK28: =SUM(AL26+AL27) -> 52929
AB29: .

Sheet PCM 07월
C1: 1 | D1: 2 | E1: 3 | F1: 4 | G1: 5 | H1: 6 | I1: 7 | J1: 8 | K1: 9 | L1: 10 | M1: 11 | N1: 12 | O1: 13 | P1: 14 | Q1: 15 | R1: 16 | S1: 17 | T1: 18 | U1: 19 | V1: 20 | W1: 21 | X1: 22 | Y1: 23 | Z1: 24 | AA1: 25 | AB1: 26 | AC1: 27 | AD1: 28 | AE1: 29 | AF1: 30 | AG1: 31 | AH1: 32 | AI1: 33 | AJ1: 34 | AK1: 35 | AL1: 36
A2: 07월 납품실적
A4: 납품실적 | B4: 업체 | C4: 화승품번 | E4: 판매단가 | F4: 1 | G4: 2 | H4: 3 | I4: 4 | J4: 5 | K4: 6 | L4: 7 | M4: 8 | N4: 9 | O4: 10 | P4: 11 | Q4: 12 | R4: 13 | S4: 14 | T4: 15 | U4: 16 | V4: 17 | W4: 18 | X4: 19 | Y4: 20 | Z4: 21 | AA4: 22 | AB4: 23 | AC4: 24 | AD4: 25 | AE4: 26 | AF4: 27 | AG4: 28 | AH4: 29 | AI4: 30 | AJ4: 31 | AK4: TOTAL | AL4: 매출금액
A5: PCM | B5: 화승T&C | D5: EN D/SIDE B FRT | E5: 1117 | AK5: =SUM(F5:AJ5) -> 0 | AL5: =E5*AK5 -> 0 | AN5: PCM 1호 | AO5: =SUM(AL5:AL175) -> 934505308
D6: EN D/SIDE B RR | E6: 1307 | AK6: =SUM(F6:AJ6) -> 0 | AL6: =E6*AK6 -> 0 | AN6: PCM 2호 | AO6: =SUM(AL177:AL177) -> 0
D7: J-300 FRT HOOD | E7: 747 | AK7: =SUM(F7:AJ7) -> 0 | AL7: =E7*AK7 -> 0 | AN7: TOTAL | AO7: =SUM(AO5:AO6) -> 934505308
D8: TQPLUG(11.8*3T) | E8: 276 | AK8: =SUM(F8:AJ8) -> 0 | AL8: =E8*AK8 -> 0
D9: FC PLUG(9.7*2T) | E9: 200 | AK9: =SUM(F9:AJ9) -> 0 | AL9: =E9*AK9 -> 0
D10: GM D/SIDE FRT(J309) | E10: 1951 | AK10: =SUM(F10:AJ10) -> 0 | AL10: =E10*AK10 -> 0
D11: GM D/SIDE RR(J309) | E11: 2042 | AK11: =SUM(F11:AJ11) -> 0 | AL11: =E11*AK11 -> 0
D12: MPV-7 HOOD(J309) | E12: 796 | AK12: =SUM(F12:AJ12) -> 0 | AL12: =E12*AK12 -> 0
D13: MPV-7 D/SIDE FRT | E13: 1941 | AK13: =SUM(F13:AJ13) -> 0 | AL13: =E13*AK13 -> 0
D14: MPV-7 D/SIDE RR | E14: 1927 | AK14: =SUM(F14:AJ14) -> 0 | AL14: =E14*AK14 -> 0
D15: VF 무절단 | E15: 450 | AK15: =SUM(F15:AJ15) -> 0 | AL15: =E15*AK15 -> 0
D16: PF D/SIDE무절단 | E16: 400 | AK16: =SUM(F16:AJ16) -> 0 | AL16: =E16*AK16 -> 0
D17: VF RR "B"(4DR)2730mm | E17: 1140 | AK17: =SUM(F17:AJ17) -> 0 | AL17: =E17*AK17 -> 0
D18: VF RR "B"(5DR)2770mm | E18: 1152 | AK18: =SUM(F18:AJ18) -> 0 | AL18: =E18*AK18 -> 0 | AM18: ㈜화승T&C TOTAL수량 | AN18: ㈜화승T&C 매출금액
D19: GM 무절단 | E19: 533 | AK19: =SUM(F19:AJ19) -> 0 | AL19: =E19*AK19 -> 0
D20: RP "B"단면 무절단 | E20: 414 | AK20: =SUM(F20:AJ20) -> 0 | AL20: =E20*AK20 -> 0 | AM20: =SUM(AK5:AK21) -> 0 | AN20: =SUM(AL5:AL21) -> 0
D21: LM 무절단 "B" | E21: 394 | AK21: =SUM(F21:AJ21) -> 0 | AL21: =E21*AK21 -> 0
B22: 오륙 | C22: G2110-0033 | D22: SC HOOD | E22: 1249 | AK22: =SUM(F22:AJ22) -> 0 | AL22: =E22*AK22 -> 0
B23: 오륙 | D23: HC HOOD | E23: 964 | AK23: =SUM(F23:AJ23) -> 0 | AL23: =E23*AK23 -> 0
B24: 오륙 | C24: G2119-0167 | D24: BDM Hood SECT "A" | E24: 953 | AK24: =SUM(F24:AJ24) -> 0 | AL24: =E24*AK24 -> 0
B25: 오륙 | C25: G1110-0175-03 | D25: MV1a HOOD SEAL (FRUNK) | E25: 1662 | AK25: =SUM(F25:AJ25) -> 0 | AL25: =E25*AK25 -> 0
B26: 오륙 | C26: G1110-0184-01 | D26: ME1a HOOD SEAL (FRUNK) | E26: 1804 | AK26: =SUM(F26:AJ26) -> 0 | AL26: =E26*AK26 -> 0
B27: 오륙 | C27: G2103-2373 | D27: CL4 D/SIDE RR "C" | E27: 1120 | K27: 1680 | R27: 1680 | Y27: 1680 | AF27: 1680 | AI27: 3360 | AK27: =SUM(F27:AJ27) -> 10080 | AL27: =E27*AK27 -> 11289600
B28: 오륙 | C28: G2103-2374 | D28: CL4 D/SIDE RR "D" | E28: 1200 | K28: 1680 | R28: 1680 | Y28: 1680 | AF28: 1680 | AI28: 3360 | AK28: =SUM(F28:AJ28) -> 10080 | AL28: =E28*AK28 -> 12096000
B29: 오륙 | C29: G2103-2225 | D29: NQ5A D/SIDE RR "C" | E29: 1089 | K29: 1680 | R29: 1680 | Y29: 1680 | AF29: 1680 | AI29: 1680 | AK29: =SUM(F29:AJ29) -> 8400 | AL29: =E29*AK29 -> 9147600
B30: 오륙 | C30: G2103-2226 | D30: NQ5A D/SIDE RR "D" | E30: 1158 | K30: 1680 | R30: 1680 | Y30: 1680 | AF30: 1680 | AI30: 1680 | AK30: =SUM(F30:AJ30) -> 8400 | AL30: =E30*AK30 -> 9727200
B31: 오륙 | C31: G1110-0050-00 | D31: HOOD CUTLINE SEAL | E31: 2157 | AK31: =SUM(F31:AJ31) -> 0 | AL31: =E31*AK31 -> 0
B32: 오륙 | C32: G1110-0147-00 | D32: KL(MCA) Hood Seal FR | E32: 1023 | AK32: =SUM(F32:AJ32) -> 0 | AL32: =E32*AK32 -> 0
B33: 오륙 | C33: G1110-0058-00 | D33: HOOD SURROUND SEAL | E33: 4526 | AK33: =SUM(F33:AJ33) -> 0 | AL33: =E33*AK33 -> 0
B34: 오륙 | C34: G1110-0050-00 | D34: UF HOOD | E34: 2157 | AK34: =SUM(F34:AJ34) -> 0 | AL34: =E34*AK34 -> 0
B35: 오륙 | C35: G1119-0066-02 | D35: HOOD SEAL | E35: 850 | AK35: =SUM(F35:AJ35) -> 0 | AL35: =E35*AK35 -> 0
B36: 오륙 | C36: G1110-0055-03 | D36: LFA Hood Seal RR | E36: 936 | AK36: =SUM(F36:AJ36) -> 0 | AL36: =E36*AK36 -> 0
B37: SHC | C37: G1142-0020-00 | D37: WK Lift Gate Cutline Seal | E37: 684 | AK37: =SUM(F37:AJ37) -> 0 | AL37: =E37*AK37 -> 0 | AM37: 서지연
B38: SHC | C38: G1100-0783-01 | D38: WK WHEEL HOUSE SEAL LH | E38: 676 | AK38: =SUM(F38:AJ38) -> 0 | AL38: =E38*AK38 -> 0 | AM38: =SUM(AL22:AL87) -> 732112080 | AN38: ='매입-매출 정리본'!K75 -> 842038080
B39: SHC | C39: G1100-0782-01 | D39: WK WHEEL HOUSE SEAL RH | E39: 676 | AK39: =SUM(F39:AJ39) -> 0 | AL39: =E39*AK39 -> 0
B40: SHC | C40: G1131-7612-01 | D40: DT SILL SEAL FRT(CREW) | E40: 849 | AK40: =SUM(F40:AJ40) -> 0 | AL40: =E40*AK40 -> 0 | AM40: =AN38+AM38 -> 1574150160
B41: SHC | C41: G1131-7613-01 | D41: DT SILL SEAL RR(CREW) | E41: 892 | AK41: =SUM(F41:AJ41) -> 0 | AL41: =E41*AK41 -> 0
...

Sheet 매입-매출 정리본
B2: 2026년 07월 매출 현황표
D3: 1 | E3: 2 | F3: 3 | G3: 4 | H3: 5 | I3: 6
B4: 공정 | C4: 차종 | D4: 아이템코드 | E4: 고객품번 | F4: P/NAME | G4: 판매단가 | H4: TOTAL | I4: 매출금액 | J4: 매출합계 | K4: SRM-정산관리상품마감 | M4: (2026년 07월) | O4: 6월 | P4: 차액
C5: PCM 매출 | J5: ='PCM 07월'!AL180 -> 934505308 | K5: =J5 -> 934505308 | M5: 금일 매출 합계 | N5: =J167 -> 2873777826 | O5: 2861636284 | P5: =N5-O5 -> 12141542
B6: 내수상품매출 | C6: 9BQC | D6: ='TPE(9410)'!C42 -> G1102-2752-00 | E6: ='TPE(9410)'!D42 -> 42933952 | F6: ='TPE(9410)'!E42 -> 9BQC FRT LH | G6: ='TPE(9410)'!F42 -> 2858 | H6: ='TPE(9410)'!AL42 -> 21400 | I6: =SUM(G6*H6) -> 61161200 | J6: =SUM(I6:I13) -> 612722880 | K6: =SUM(J6:J72) -> 1090991350
D7: ='TPE(9410)'!C43 -> G1102-2753-00 | E7: ='TPE(9410)'!D43 -> 42933953 | F7: ='TPE(9410)'!E43 -> 9BQC FRT RH | G7: ='TPE(9410)'!F43 -> 2858 | H7: ='TPE(9410)'!AL43 -> 21200 | I7: =SUM(G7*H7) -> 60589600
D8: ='TPE(9410)'!C46 -> G1102-2754-00 | E8: ='TPE(9410)'!D46 -> 42933956 | F8: ='TPE(9410)'!E46 -> 9BQC RR LH(TNI) | G8: ='TPE(9410)'!F46 -> 10598 | H8: ='TPE(9410)'!AL46 -> 780 | I8: =SUM(G8*H8) -> 8266440 | M8: 금일 매입 합계 | N8: =자재매입!J322 -> 1.8311475e+09 | O8: 1759147753 | P8: =N8-O8 -> 71999790
D9: ='TPE(9410)'!C47 -> G1102-2755-00 | E9: ='TPE(9410)'!D47 -> 42933957 | F9: ='TPE(9410)'!E47 -> 9BQC RR RH(TNI) | G9: ='TPE(9410)'!F47 -> 10598 | H9: ='TPE(9410)'!AL47 -> 780 | I9: =SUM(G9*H9) -> 8266440
D10: ='TPE(9410)'!C44 -> G1102-2756-00 | E10: ='TPE(9410)'!D44 -> 42933958 | F10: ='TPE(9410)'!E44 -> 9BQC RR LH(PRI) | G10: ='TPE(9410)'!F44 -> 11028 | H10: ='TPE(9410)'!AL44 -> 21480 | I10: =SUM(G10*H10) -> 236881440
D11: ='TPE(9410)'!C45 -> G1102-2757-00 | E11: ='TPE(9410)'!D45 -> 42933959 | F11: ='TPE(9410)'!E45 -> 9BQC RR RH(PRI) | G11: ='TPE(9410)'!F45 -> 11028 | H11: ='TPE(9410)'!AL45 -> 21420 | I11: =SUM(G11*H11) -> 236219760
D12: ='TPE(9410)'!C48 -> G1102-2463-00 | E12: ='TPE(9410)'!D48 -> 42870825 | F12: ='TPE(9410)'!E48 -> 9BQC Glass run RR RH PRIVACY | G12: ='TPE(9410)'!F48 -> 10627 | H12: ='TPE(9410)'!AL48 -> 100 | I12: =SUM(G12*H12) -> 1062700
D13: ='TPE(9410)'!C49 -> G1102-2544-00 | E13: ='TPE(9410)'!D49 -> 42896296 | F13: ='TPE(9410)'!E49 -> 9BQC Glass run FR RH | G13: ='TPE(9410)'!F49 -> 2753 | H13: ='TPE(9410)'!AL49 -> 100 | I13: =SUM(G13*H13) -> 275300
C14: JA | D14: ='TPE(9410)'!C16 -> G1102-1361-00 | E14: ='TPE(9410)'!D16 -> 82530G6000 | F14: G/RUN FRT LH | G14: ='TPE(9410)'!F16 -> 2558 | H14: ='TPE(9410)'!AL16 -> 10235 | I14: =SUM(G14*H14) -> 26181130 | J14: =SUM(I14:I19) -> 120024682
D15: ='TPE(9410)'!C17 -> G1102-1362-00 | E15: ='TPE(9410)'!D17 -> 82540G6000 | F15: G/RUN FRT RH | G15: ='TPE(9410)'!F17 -> 2558 | H15: ='TPE(9410)'!AL17 -> 10225 | I15: =SUM(G15*H15) -> 26155550
D16: ='TPE(9410)'!C18 -> R1102-1363-00 | E16: ='TPE(9410)'!D18 -> 83530G6000 | F16: G/RUN RR LH | G16: ='TPE(9410)'!F18 -> 3443 | H16: ='TPE(9410)'!AL18 -> 9800 | I16: =SUM(G16*H16) -> 33741400
D17: ='TPE(9410)'!C19 -> R1102-1364-00 | E17: ='TPE(9410)'!D19 -> 83540G6000 | F17: G/RUN RR RH | G17: ='TPE(9410)'!F19 -> 3443 | H17: ='TPE(9410)'!AL19 -> 9800 | I17: =SUM(G17*H17) -> 33741400
D18: ='TPE(9410)'!C20 -> G1102-1363-01 | E18: ='TPE(9410)'!D20 -> 83530G6000 | F18: G/RUN RR RH | G18: ='TPE(9410)'!F20 -> 3478 | H18: ='TPE(9410)'!AL20 -> 29 | I18: =SUM(G18*H18) -> 100862
D19: ='TPE(9410)'!C21 -> G1102-1364-01 | E19: ='TPE(9410)'!D21 -> 83540G6000 | F19: G/RUN RR RH | G19: ='TPE(9410)'!F21 -> 3478 | H19: ='TPE(9410)'!AL21 -> 30 | I19: =SUM(G19*H19) -> 104340
C20: HR | D20: ='TPE(9410)'!C6 -> G1102-0085 | E20: ='TPE(9410)'!D6 -> 825304F000 | F20: G/RUN FRT LH | G20: ='TPE(9410)'!F6 -> 2664 | H20: ='TPE(9410)'!AL6 -> 7898 | I20: =SUM(G20*H20) -> 21040272 | J20: =SUM(I20:I23) -> 46713696
D21: ='TPE(9410)'!C7 -> G1102-0128 | E21: ='TPE(9410)'!D7 -> 825404F000 | F21: G/RUN FRT RH | G21: ='TPE(9410)'!F7 -> 2664 | H21: ='TPE(9410)'!AL7 -> 7882 | I21: =SUM(G21*H21) -> 20997648
D22: ='TPE(9410)'!C8 -> G1102-0181 | E22: ='TPE(9410)'!D8 -> 835304F000 | F22: G/RUN RR LH | G22: ='TPE(9410)'!F8 -> 2272 | H22: ='TPE(9410)'!AL8 -> 1027 | I22: =SUM(G22*H22) -> 2333344
D23: ='TPE(9410)'!C9 -> G1102-0218 | E23: ='TPE(9410)'!D9 -> 835404F000 | F23: G/RUN RR RH | G23: ='TPE(9410)'!F9 -> 2272 | H23: ='TPE(9410)'!AL9 -> 1031 | I23: =SUM(G23*H23) -> 2342432
C24: PU | D24: ='PVC(9410)'!C6 -> G1106-0179 | E24: ='PVC(9410)'!D6 -> 822104E000 | F24: ='PVC(9410)'!E6 -> PU OUT CHAN LH | G24: ='PVC(9410)'!F6 -> 3275 | H24: ='PVC(9410)'!AL6 -> 7279 | I24: =SUM(G24*H24) -> 23838725 | J24: =SUM(I24:I31) -> 65083314
D25: ='PVC(9410)'!C7 -> G1106-0180 | E25: ='PVC(9410)'!D7 -> 822204E000 | F25: ='PVC(9410)'!E7 -> PU OUT CHAN RH | G25: ='PVC(9410)'!F7 -> 3275 | H25: ='PVC(9410)'!AL7 -> 7271 | I25: =SUM(G25*H25) -> 23812525
D26: ='PVC(9410)'!C8 -> G1102-0620 | E26: ='PVC(9410)'!D8 -> 832104E000 | F26: ='PVC(9410)'!E8 -> PU(D/CAB) OTR BELT LH | G26: ='PVC(9410)'!F8 -> 2592 | H26: ='PVC(9410)'!AL8 -> 647 | I26: =SUM(G26*H26) -> 1677024
D27: ='PVC(9410)'!C9 -> G1102-0621 | E27: ='PVC(9410)'!D9 -> 832204E000 | F27: ='PVC(9410)'!E9 -> PU(D/CAB) OTR BELT RH | G27: ='PVC(9410)'!F9 -> 2592 | H27: ='PVC(9410)'!AL9 -> 620 | I27: =SUM(G27*H27) -> 1607040
D28: ='PVC(9410)'!C10 -> G1106-0179-01 | E28: ='PVC(9410)'!D10 -> 822104E000 | F28: ='PVC(9410)'!E10 -> PU Outer Belt FR LH | G28: ='PVC(9410)'!F10 -> 3275 | H28: ='PVC(9410)'!AL10 -> 2160 | I28: =SUM(G28*H28) -> 7074000
D29: ='PVC(9410)'!C11 -> G1106-0180-01 | E29: ='PVC(9410)'!D11 -> 822204E000 | F29: ='PVC(9410)'!E11 -> PU Outer Belt FR RH | G29: ='PVC(9410)'!F11 -> 3275 | H29: ='PVC(9410)'!AL11 -> 2160 | I29: =SUM(G29*H29) -> 7074000
D30: ='PVC(9410)'!C12 -> G1102-0620-01 | E30: ='PVC(9410)'!D12 -> 832104E000 | F30: ='PVC(9410)'!E12 -> PU(D/CAB) OTR BELT LH | G30: ='PVC(9410)'!F12 -> 2494 | H30: ='PVC(9410)'!AL12 -> 0 | I30: =SUM(G30*H30) -> 0
D31: ='PVC(9410)'!C13 -> G1102-0621-01 | E31: ='PVC(9410)'!D13 -> 832204E000 | F31: ='PVC(9410)'!E13 -> PU(D/CAB) OTR BELT RH | G31: ='PVC(9410)'!F13 -> 2494 | H31: ='PVC(9410)'!AL13 -> 0 | I31: =SUM(G31*H31) -> 0
C32: GV | D32: ='PVC(9410)'!C14 -> G1106-0212 | E32: 821707M000 | F32: OTR CHAN LH | G32: ='PVC(9410)'!F14 -> 2477 | H32: ='PVC(9410)'!AL14 -> 830 | I32: =SUM(G32*H32) -> 2055910 | J32: =SUM(I32:I33) -> 4087050
D33: ='PVC(9410)'!C15 -> G1106-0213 | E33: 821807M000 | F33: OTR CHAN RH | G33: ='PVC(9410)'!F15 -> 2477 | H33: ='PVC(9410)'!AL15 -> 820 | I33: =SUM(G33*H33) -> 2031140 | L33: 다솜 수정마감
C34: QZ | D34: ='PVC(9410)'!C16 -> G1106-0317-00 | E34: 821707P000 | F34: OTR CHAN LH | G34: ='PVC(9410)'!F16 -> 2150 | H34: ='PVC(9410)'!AL16 -> 673 | I34: =SUM(G34*H34) -> 1446950 | J34: =SUM(I34:I35) -> 2719033 | L34: =K6+L117 -> 1092198238
D35: ='PVC(9410)'!C17 -> G1106-0318-00 | E35: 821807P000 | F35: OTR CHAN RH | G35: ='PVC(9410)'!F17 -> 1879 | H35: ='PVC(9410)'!AL17 -> 677 | I35: =SUM(G35*H35) -> 1272083
C36: VT | D36: ='PVC(9410)'!C18 -> G1106-0669-00 | E36: 81151-5H000 | F36: INR CHAN LH | G36: ='PVC(9410)'!F18 -> 2477 | H36: ='PVC(9410)'!$AL$20 -> 0 | I36: =SUM(G36*H36) -> 0 | J36: =SUM(I36:I37) -> 0
D37: ='PVC(9410)'!C19 -> G1106-0670-00 | E37: 81161-5H000 | F37: INR CHAN RH | G37: ='PVC(9410)'!F19 -> 2477 | H37: ='PVC(9410)'!$AL$20 -> 0 | I37: =SUM(G37*H37) -> 0
C38: EG | D38: ='PVC(9410)'!C20 -> 0 | E38: 81151-7A000 | F38: INR CHAN LH | G38: ='PVC(9410)'!F20 -> 2496 | H38: ='PVC(9410)'!AL20 -> 0 | I38: =SUM(G38*H38) -> 0 | J38: =SUM(I38:I41) -> 569904
D39: ='PVC(9410)'!C21 -> 0 | E39: 81161-7A000 | F39: INR CHAN RH | G39: ='PVC(9410)'!F21 -> 2496 | H39: ='PVC(9410)'!AL21 -> 0 | I39: =SUM(G39*H39) -> 0
D40: ='PVC(9410)'!C24 -> G1106-0009 | E40: 821707A000 | F40: OTR CHAN LH | G40: ='PVC(9410)'!F24 -> 2298 | H40: ='PVC(9410)'!AL24 -> 92 | I40: =SUM(G40*H40) -> 211416
D41: ='PVC(9410)'!C25 -> G1106-0010 | E41: 821807A000 | F41: OTR CHAN RH | G41: ='PVC(9410)'!F25 -> 2298 | H41: ='PVC(9410)'!AL25 -> 156 | I41: =SUM(G41*H41) -> 358488
...

Sheet 자재매입
A1: 2026년 07월 자재매입금액
A2: 순서 | B2: 자재코드 | C2: 품명 및 규격 | D2: 단위 | E2: 차종 | F2: 구매처 | G2: 단가 | H2: 구매량 | I2: 금액 | J2: 당월합계 | K2: 26.6 마감 | L2: 차액 | R2: 분류 | S2: 순 | T2: 품명 및 규격 | U2: 구매량 | V2: 금액 | AO2: 매출 | AP2: 매입 | AQ2: 인건비 | AR2: 인원
A3: 9BQC 매입 | B3: 3107-0054 | C3: UPR Bracket LH | D3: EA | E3: 9BQC | F3: 경기금속 | G3: 169 | H3: =원자재매입내역!AL7 -> 24000 | I3: =G3*H3 -> 4056000 | J3: =SUM(I3:I4) -> 8112000 | K3: 8112000 | L3: =J3-K3 -> 0 | R3: 9BQC | S3: =COUNTIF($R$3:R3,R3) -> 1 | T3: =C3 -> UPR Bracket LH | U3: =H3 -> 24000 | V3: =I3 -> 4056000 | X3: Kategorie | Z3: 총금액
B4: 3107-0055 | C4: UPR Bracket RH | D4: EA | G4: 169 | H4: =원자재매입내역!AL8 -> 24000 | I4: =G4*H4 -> 4056000 | R4: 9BQC | S4: =COUNTIF($R$3:R4,R4) -> 2 | T4: =C4 -> UPR Bracket RH | U4: =H4 -> 24000 | V4: =I4 -> 4056000 | X4: 압출 PCM | Z4: =SUM(AB7:AB164) -> 4.9579576e+08
B5: 3109-0182 | C5: 9BQC PRI LH | D5: EA | F5: 글라스 ㈜지텍 납품 | G5: 2492 | H5: =부자재매입내역!AL143 -> 23052 | I5: =G5*H5 -> 57445584 | J5: =SUM(I5:I8) -> 119518532 | K5: 120281364 | L5: =J5-K5 -> -762832 | M5: =J5+J112 -> 204842532 | R5: 9BQC | S5: =COUNTIF($R$3:R5,R5) -> 3 | T5: =C5 -> 9BQC PRI LH | U5: =H5 -> 23052 | V5: =I5 -> 57445584 | AG5: XA1-65B | AH5: 지수 | AI5: 출하수 | AJ5: 계산 | AK5: 사용비
B6: 3109-0183 | C6: 9BQC PRI RH | D6: EA | G6: 2492 | H6: =부자재매입내역!AL144 -> 23039 | I6: =G6*H6 -> 57413188 | R6: 9BQC | S6: =COUNTIF($R$3:R6,R6) -> 4 | T6: =C6 -> 9BQC PRI RH | U6: =H6 -> 23039 | V6: =I6 -> 57413188 | X6: Kategorie | Y6: 순 | Z6: 품명 및 규격 | AA6: 구매량 | AB6: 금액 | AD6: Kategorie | AE6: 매 입 금 액 | AG6: 9BQC FRT | AH6: 111764 | AI6: =SUM('[4]TPE(9410)'!AL42:AL43) -> 21800 | AJ6: =AI6*AH6 -> 2436455200
B7: 3109-0184 | C7: 9BQC TNTD LH | D7: EA | G7: 2120 | H7: =부자재매입내역!AL145 -> 1099 | I7: =G7*H7 -> 2329880 | R7: 9BQC | S7: =COUNTIF($R$3:R7,R7) -> 5 | T7: =C7 -> 9BQC TNTD LH | U7: =H7 -> 1099 | V7: =I7 -> 2329880 | X7: =$X$4 -> 압출 PCM | Y7: =ROW()-6 -> 1 | Z7: {=IFERROR(INDEX($T$3:$T$373,MATCH(1,($X7=$R$3:$R$373)*($Y7=$S$3:$S$373),0))," ")} -> 0.45*30 | AA7: {=IFERROR(INDEX($U$3:$U$373,MATCH(1,($X7=$R$3:$R$373)*($Y7=$S$3:$S$373),0))," ")} -> 0 | AB7: {=IFERROR(INDEX($V$3:$V$373,MATCH(1,($X7=$R$3:$R$373)*($Y7=$S$3:$S$373),0))," ")} -> 0 | AD7: 9BQC | AE7: =SUMIF($R$3:$R$373,AD7,$V$3:$V$373) -> 3.7743029e+08 | AG7: 9BQC RR | AH7: 59326 | AI7: =SUM('[4]TPE(9410)'!AL44:AL47) -> 20480 | AJ7: =AI7*AH7 -> 1214996480
B8: 3109-0185 | C8: 9BQC TNTD RH | D8: EA | G8: 2120 | H8: =부자재매입내역!AL146 -> 1099 | I8: =G8*H8 -> 2329880 | M8: 세동단가인상 | R8: 9BQC | S8: =COUNTIF($R$3:R8,R8) -> 6 | T8: =C8 -> 9BQC TNTD RH | U8: =H8 -> 1099 | V8: =I8 -> 2329880 | X8: =$X$4 -> 압출 PCM | Y8: =ROW()-6 -> 2 | Z8: {=IFERROR(INDEX($T$3:$T$373,MATCH(1,($X8=$R$3:$R$373)*($Y8=$S$3:$S$373),0))," ")} -> 0.5*30 | AA8: {=IFERROR(INDEX($U$3:$U$373,MATCH(1,($X8=$R$3:$R$373)*($Y8=$S$3:$S$373),0))," ")} -> 0 | AB8: {=IFERROR(INDEX($V$3:$V$373,MATCH(1,($X8=$R$3:$R$373)*($Y8=$S$3:$S$373),0))," ")} -> 0 | AD8: TPE | AE8: =SUMIF($R$3:$R$373,AD8,$V$3:$V$373) -> 1.1812613e+08 | AG8: 9BQC TOTAL | AJ8: =SUM(AJ6:AJ7) -> 3651451680 | AK8: =AJ8/(SUM($AJ$8,$AJ$14)) -> 0.59593609
B9: 42823723 | C9: 9BQC D/V BAR LH | D9: EA | F9: ㈜ 세동 | G9: 1972 | H9: =부자재매입내역!AL218 -> 21474 | I9: =H9*G9 -> 42346728 | J9: =SUM(I9:I10) -> 84719092 | K9: 106790404 | L9: =J9-K9 -> -22071312 | M9: 82399198 | N9: 기존 | R9: 9BQC | S9: =COUNTIF($R$3:R9,R9) -> 7 | T9: =C9 -> 9BQC D/V BAR LH | U9: =H9 -> 21474 | V9: =I9 -> 42346728 | X9: =$X$4 -> 압출 PCM | Y9: =ROW()-6 -> 3 | Z9: {=IFERROR(INDEX($T$3:$T$373,MATCH(1,($X9=$R$3:$R$373)*($Y9=$S$3:$S$373),0))," ")} -> 0.5*21.3 | AA9: {=IFERROR(INDEX($U$3:$U$373,MATCH(1,($X9=$R$3:$R$373)*($Y9=$S$3:$S$373),0))," ")} -> 0 | AB9: {=IFERROR(INDEX($V$3:$V$373,MATCH(1,($X9=$R$3:$R$373)*($Y9=$S$3:$S$373),0))," ")} -> 0 | AD9: 압출 PCM | AE9: =SUMIF($R$3:$R$373,AD9,$V$3:$V$373) -> 4.9579576e+08
B10: 42823724 | C10: 9BQC D/V BAR RH | D10: EA | G10: 1972 | H10: =부자재매입내역!AL219 -> 21487 | I10: =H10*G10 -> 42372364 | M10: =J9-M9 -> 2319894 | N10: 인상폭 | R10: 9BQC | S10: =COUNTIF($R$3:R10,R10) -> 8 | T10: =C10 -> 9BQC D/V BAR RH | U10: =H10 -> 21487 | V10: =I10 -> 42372364 | X10: =$X$4 -> 압출 PCM | Y10: =ROW()-6 -> 4 | Z10: {=IFERROR(INDEX($T$3:$T$373,MATCH(1,($X10=$R$3:$R$373)*($Y10=$S$3:$S$373),0))," ")} -> 0.5*34 | AA10: {=IFERROR(INDEX($U$3:$U$373,MATCH(1,($X10=$R$3:$R$373)*($Y10=$S$3:$S$373),0))," ")} -> 0 | AB10: {=IFERROR(INDEX($V$3:$V$373,MATCH(1,($X10=$R$3:$R$373)*($Y10=$S$3:$S$373),0))," ")} -> 0 | AD10: PVC | AE10: =SUMIF($R$3:$R$373,AD10,$V$3:$V$373) -> 31907118 | AG10: 9BQB C | AH10: 111600 | AI10: ='[4]PCM 05월'!AK81 -> 3000 | AJ10: =AI10*AH10 -> 334800000
B11: 3103-0686 | C11: 아마쉘 PAD 5T*5W*60L | D11: EA | F11: 우봉 | G11: 9.2 | H11: =부자재매입내역!AL220 -> 156000 | I11: =H11*G11 -> 1435200 | J11: =SUM(I11:I14) -> 2479300 | K11: 2531900 | R11: 9BQC | S11: =COUNTIF($R$3:R11,R11) -> 9 | T11: =C11 -> 아마쉘 PAD 5T*5W*60L | U11: =H11 -> 156000 | V11: =I11 -> 1435200 | X11: =$X$4 -> 압출 PCM | Y11: =ROW()-6 -> 5 | Z11: {=IFERROR(INDEX($T$3:$T$373,MATCH(1,($X11=$R$3:$R$373)*($Y11=$S$3:$S$373),0))," ")} -> 압연심금 0.45*28 | AA11: {=IFERROR(INDEX($U$3:$U$373,MATCH(1,($X11=$R$3:$R$373)*($Y11=$S$3:$S$373),0))," ")} -> 0 | AB11: {=IFERROR(INDEX($V$3:$V$373,MATCH(1,($X11=$R$3:$R$373)*($Y11=$S$3:$S$373),0))," ")} -> 0 | AD11: EPDM 상품 | AE11: =SUMIF($R$3:$R$373,AD11,$V$3:$V$373) -> 7.0117058e+08 | AG11: JA FRT | AH11: 135049.8 | AI11: =SUM('[4]TPE(9410)'!AL16:AL17) -> 9120 | AJ11: =AI11*AH11 -> 1231654176
B12: 3103-0832 | C12: 아마쉘 PAD 7T*10W*50L | D12: EA | G12: 19.7 | H12: =부자재매입내역!AL221 -> 53000 | I12: =H12*G12 -> 1044100 | R12: 9BQC | S12: =COUNTIF($R$3:R12,R12) -> 10 | T12: =C12 -> 아마쉘 PAD 7T*10W*50L | U12: =H12 -> 53000 | V12: =I12 -> 1044100 | X12: =$X$4 -> 압출 PCM | Y12: =ROW()-6 -> 6 | Z12: {=IFERROR(INDEX($T$3:$T$373,MATCH(1,($X12=$R$3:$R$373)*($Y12=$S$3:$S$373),0))," ")} -> 46MM WIRE CARRIER(05R-159) | AA12: {=IFERROR(INDEX($U$3:$U$373,MATCH(1,($X12=$R$3:$R$373)*($Y12=$S$3:$S$373),0))," ")} -> 48550 | AB12: {=IFERROR(INDEX($V$3:$V$373,MATCH(1,($X12=$R$3:$R$373)*($Y12=$S$3:$S$373),0))," ")} -> 15730200 | AD12: 합계 | AE12: =SUM(AE6:AE11) -> 1.7244299e+09 | AG12: JA RR | AH12: 103335 | AI12: =SUM('[4]TPE(9410)'!AL18:AL19) -> 8800 | AJ12: =AI12*AH12 -> 909348000
C13: 아마쉘 PAD 1.5*20*20 | D13: EA | G13: 15.8 | H13: =부자재매입내역!AL222 -> 0 | I13: =H13*G13 -> 0 | R13: 9BQC | S13: =COUNTIF($R$3:R13,R13) -> 11 | T13: =C13 -> 아마쉘 PAD 1.5*20*20 | U13: =H13 -> 0 | V13: =I13 -> 0 | X13: =$X$4 -> 압출 PCM | Y13: =ROW()-6 -> 7 | Z13: {=IFERROR(INDEX($T$3:$T$373,MATCH(1,($X13=$R$3:$R$373)*($Y13=$S$3:$S$373),0))," ")} -> W60712$2 | AA13: {=IFERROR(INDEX($U$3:$U$373,MATCH(1,($X13=$R$3:$R$373)*($Y13=$S$3:$S$373),0))," ")} -> 41872 | AB13: {=IFERROR(INDEX($V$3:$V$373,MATCH(1,($X13=$R$3:$R$373)*($Y13=$S$3:$S$373),0))," ")} -> 146970720 | AG13: QX D | AH13: 69825 | AI13: ='[4]PCM 05월'!AK112 -> 0 | AJ13: =AI13*AH13 -> 0
B14: 3103-0696 | C14: 아마쉘 PAD 3*6*90 | D14: EA | G14: 12.2 | H14: =부자재매입내역!AL223 -> 0 | I14: =H14*G14 -> 0 | R14: 9BQC | S14: =COUNTIF($R$3:R14,R14) -> 12 | T14: =C14 -> 아마쉘 PAD 3*6*90 | U14: =H14 -> 0 | V14: =I14 -> 0 | X14: =$X$4 -> 압출 PCM | Y14: =ROW()-6 -> 8 | Z14: {=IFERROR(INDEX($T$3:$T$373,MATCH(1,($X14=$R$3:$R$373)*($Y14=$S$3:$S$373),0))," ")} -> W60712$2TA | AA14: {=IFERROR(INDEX($U$3:$U$373,MATCH(1,($X14=$R$3:$R$373)*($Y14=$S$3:$S$373),0))," ")} -> 7168 | AB14: {=IFERROR(INDEX($V$3:$V$373,MATCH(1,($X14=$R$3:$R$373)*($Y14=$S$3:$S$373),0))," ")} -> 23941120 | AG14: TPE TOTAL | AJ14: =SUM(AJ10:AJ13) -> 2475802176 | AK14: =AJ14/(SUM($AJ$8,$AJ$14)) -> 0.40406391
A15: 심금류 | B15: 31020015 | C15: SUS430(0.4*51*3) | D15: Kg | E15: 개발 | G15: 450 | H15: =원자재매입내역!AL3 -> 0 | I15: =G15*H15 -> 0 | J15: =SUM(I17:I18) -> 0 | K15: 0 | M15: =J15+J3 -> 8112000 | R15: PVC | S15: =COUNTIF($R$3:R15,R15) -> 1 | T15: =C15 -> SUS430(0.4*51*3) | U15: =H15 -> 0 | V15: =I15 -> 0 | X15: =$X$4 -> 압출 PCM | Y15: =ROW()-6 -> 9 | Z15: {=IFERROR(INDEX($T$3:$T$373,MATCH(1,($X15=$R$3:$R$373)*($Y15=$S$3:$S$373),0))," ")} -> W60594BJ2 | AA15: {=IFERROR(INDEX($U$3:$U$373,MATCH(1,($X15=$R$3:$R$373)*($Y15=$S$3:$S$373),0))," ")} -> 13454 | AB15: {=IFERROR(INDEX($V$3:$V$373,MATCH(1,($X15=$R$3:$R$373)*($Y15=$S$3:$S$373),0))," ")} -> 59332140
B16: 31020023 | C16: 0.6*36 | D16: Kg | G16: 1 | H16: =원자재매입내역!AL4 -> 0 | I16: =G16*H16 -> 0 | R16: PVC | S16: =COUNTIF($R$3:R16,R16) -> 2 | T16: =C16 -> 0.6*36 | U16: =H16 -> 0 | V16: =I16 -> 0 | X16: =$X$4 -> 압출 PCM | Y16: =ROW()-6 -> 10 | Z16: {=IFERROR(INDEX($T$3:$T$373,MATCH(1,($X16=$R$3:$R$373)*($Y16=$S$3:$S$373),0))," ")} -> W60515 | AA16: {=IFERROR(INDEX($U$3:$U$373,MATCH(1,($X16=$R$3:$R$373)*($Y16=$S$3:$S$373),0))," ")} -> 0 | AB16: {=IFERROR(INDEX($V$3:$V$373,MATCH(1,($X16=$R$3:$R$373)*($Y16=$S$3:$S$373),0))," ")} -> 0
B17: 31020025 | C17: SCP1-1/2 H (0.5*50*5) | D17: Kg | E17: EG,GV,QZ OUT | F17: 경기금속 | G17: 1350 | H17: =원자재매입내역!AL5 -> 0 | I17: =G17*H17 -> 0 | L17: =K15-J15 -> 0 | R17: PVC | S17: =COUNTIF($R$3:R17,R17) -> 3 | T17: =C17 -> SCP1-1/2 H (0.5*50*5) | U17: =H17 -> 0 | V17: =I17 -> 0 | X17: =$X$4 -> 압출 PCM | Y17: =ROW()-6 -> 11 | Z17: {=IFERROR(INDEX($T$3:$T$373,MATCH(1,($X17=$R$3:$R$373)*($Y17=$S$3:$S$373),0))," ")} -> W60052 | AA17: {=IFERROR(INDEX($U$3:$U$373,MATCH(1,($X17=$R$3:$R$373)*($Y17=$S$3:$S$373),0))," ")} -> 7934 | AB17: {=IFERROR(INDEX($V$3:$V$373,MATCH(1,($X17=$R$3:$R$373)*($Y17=$S$3:$S$373),0))," ")} -> 32608740 | AN17: JA HR | AO17: =SUM('TPE(9410)'!AN9,'TPE(9410)'!AN19) -> 46713696 | AP17: =#REF! -> #REF! | AQ17: =(3000000*7)+(2000000*7)+(3200000*2) -> 41400000 | AR17: 16 | AS17: =AO17-#REF!-AQ17 -> #REF!
B18: 31020026 | C18: 0.5*32(연질아연도금) | D18: Kg | E18: VT INR | G18: 1720 | H18: =원자재매입내역!AL6 -> 0 | I18: =G18*H18 -> 0 | R18: PVC | S18: =COUNTIF($R$3:R18,R18) -> 4 | T18: =C18 -> 0.5*32(연질아연도금) | U18: =H18 -> 0 | V18: =I18 -> 0 | X18: =$X$4 -> 압출 PCM | Y18: =ROW()-6 -> 12 | Z18: {=IFERROR(INDEX($T$3:$T$373,MATCH(1,($X18=$R$3:$R$373)*($Y18=$S$3:$S$373),0))," ")} -> S6073RN4 | AA18: {=IFERROR(INDEX($U$3:$U$373,MATCH(1,($X18=$R$3:$R$373)*($Y18=$S$3:$S$373),0))," ")} -> 0 | AB18: {=IFERROR(INDEX($V$3:$V$373,MATCH(1,($X18=$R$3:$R$373)*($Y18=$S$3:$S$373),0))," ")} -> 0 | AN18: PD | AO18: ='OWF10(상품)'!AN25 -> 0 | AP18: =#REF! -> #REF! | AQ18: =(2200000*6) -> 13200000 | AR18: 6 | AS18: =AO18-#REF!-AQ18 -> #REF!
B19: 12457812 | C19: 0.45*30 | D19: M | E19: 유일고무,CTR | F19: ㈜부미 | G19: 127 | H19: =원자재매입내역!AL9 -> 0 | I19: =G19*H19 -> 0 | J19: =SUM(I19:I23) -> 0 | L19: =K19-J19 -> 0 | R19: 압출 PCM | S19: =COUNTIF($R$3:R19,R19) -> 1 | T19: =C19 -> 0.45*30 | U19: =H19 -> 0 | V19: =I19 -> 0 | X19: =$X$4 -> 압출 PCM | Y19: =ROW()-6 -> 13 | Z19: {=IFERROR(INDEX($T$3:$T$373,MATCH(1,($X19=$R$3:$R$373)*($Y19=$S$3:$S$373),0))," ")} -> W60921 | AA19: {=IFERROR(INDEX($U$3:$U$373,MATCH(1,($X19=$R$3:$R$373)*($Y19=$S$3:$S$373),0))," ")} -> 0 | AB19: {=IFERROR(INDEX($V$3:$V$373,MATCH(1,($X19=$R$3:$R$373)*($Y19=$S$3:$S$373),0))," ")} -> 0 | AN19: PCM | AO19: =#REF!-#REF!+(2600*#REF!) -> #REF! | AP19: =#REF! -> #REF! | AQ19: =3200000*6 -> 19200000 | AR19: 6 | AS19: =AO19-#REF!-AQ19 -> #REF!
B20: 12457813 | C20: 0.5*30 | D20: M | E20: 엑셀 오프닝 | G20: 107 | H20: =원자재매입내역!AL10 -> 0 | I20: =G20*H20 -> 0 | R20: 압출 PCM | S20: =COUNTIF($R$3:R20,R20) -> 2 | T20: =C20 -> 0.5*30 | U20: =H20 -> 0 | V20: =I20 -> 0 | X20: =$X$4 -> 압출 PCM | Y20: =ROW()-6 -> 14 | Z20: {=IFERROR(INDEX($T$3:$T$373,MATCH(1,($X20=$R$3:$R$373)*($Y20=$S$3:$S$373),0))," ")} -> S6998RT2 | AA20: {=IFERROR(INDEX($U$3:$U$373,MATCH(1,($X20=$R$3:$R$373)*($Y20=$S$3:$S$373),0))," ")} -> 0 | AB20: {=IFERROR(INDEX($V$3:$V$373,MATCH(1,($X20=$R$3:$R$373)*($Y20=$S$3:$S$373),0))," ")} -> 0 | AQ20: =AR20*2300000 -> 13800000 | AR20: 6 | AS20: =AQ20 -> 13800000
B21: 12457814 | C21: 0.5*21.3 | D21: M | E21: 수승화학 | G21: 115 | H21: =원자재매입내역!AL11 -> 0 | I21: =G21*H21 -> 0 | R21: 압출 PCM | S21: =COUNTIF($R$3:R21,R21) -> 3 | T21: =C21 -> 0.5*21.3 | U21: =H21 -> 0 | V21: =I21 -> 0 | X21: =$X$4 -> 압출 PCM | Y21: =ROW()-6 -> 15 | Z21: {=IFERROR(INDEX($T$3:$T$373,MATCH(1,($X21=$R$3:$R$373)*($Y21=$S$3:$S$373),0))," ")} -> W60593$W3 | AA21: {=IFERROR(INDEX($U$3:$U$373,MATCH(1,($X21=$R$3:$R$373)*($Y21=$S$3:$S$373),0))," ")} -> 9110 | AB21: {=IFERROR(INDEX($V$3:$V$373,MATCH(1,($X21=$R$3:$R$373)*($Y21=$S$3:$S$373),0))," ")} -> 39537400 | AQ21: =AR21*3500000 -> 31500000 | AR21: 9 | AS21: =AQ21 -> 31500000
B22: 12345698 | C22: 0.5*34 | D22: M | G22: 144 | H22: =원자재매입내역!AL12 -> 0 | I22: =G22*H22 -> 0 | M22: =J24*1.1 -> 9505141.8 | R22: 압출 PCM | S22: =COUNTIF($R$3:R22,R22) -> 4 | T22: =C22 -> 0.5*34 | U22: =H22 -> 0 | V22: =I22 -> 0 | X22: =$X$4 -> 압출 PCM | Y22: =ROW()-6 -> 16 | Z22: {=IFERROR(INDEX($T$3:$T$373,MATCH(1,($X22=$R$3:$R$373)*($Y22=$S$3:$S$373),0))," ")} -> W60054 | AA22: {=IFERROR(INDEX($U$3:$U$373,MATCH(1,($X22=$R$3:$R$373)*($Y22=$S$3:$S$373),0))," ")} -> 2087 | AB22: {=IFERROR(INDEX($V$3:$V$373,MATCH(1,($X22=$R$3:$R$373)*($Y22=$S$3:$S$373),0))," ")} -> 8076690 | AO22: =SUM(AO17:AO21) -> #REF! | AP22: =SUM(AP17:AP21) -> #REF! | AQ22: =SUM(AQ17:AQ21) -> 119100000 | AS22: =SUM(AS17:AS21) -> #REF! | AT22: =AO22-#REF!-AQ22 -> #REF!
B23: 31020035 | C23: 압연심금 0.45*28 | D23: M | E23: 알피아이코리아 | G23: 127 | H23: =원자재매입내역!AL13 -> 0 | I23: =G23*H23 -> 0 | R23: 압출 PCM | S23: =COUNTIF($R$3:R23,R23) -> 5 | T23: =C23 -> 압연심금 0.45*28 | U23: =H23 -> 0 | V23: =I23 -> 0 | X23: =$X$4 -> 압출 PCM | Y23: =ROW()-6 -> 17 | Z23: {=IFERROR(INDEX($T$3:$T$373,MATCH(1,($X23=$R$3:$R$373)*($Y23=$S$3:$S$373),0))," ")} -> W60596 | AA23: {=IFERROR(INDEX($U$3:$U$373,MATCH(1,($X23=$R$3:$R$373)*($Y23=$S$3:$S$373),0))," ")} -> 0 | AB23: {=IFERROR(INDEX($V$3:$V$373,MATCH(1,($X23=$R$3:$R$373)*($Y23=$S$3:$S$373),0))," ")} -> 0 | AS23: 기타경비 | AT23: 80000000
B24: 31020032 | C24: 심금STS430A 0.4*45.5 | D24: Kg | E24: PU | F24: 우진금속 | G24: 2649 | H24: =원자재매입내역!AL14 -> 3262 | I24: =G24*H24 -> 8641038 | J24: =I24 -> 8641038 | K24: 10890039 | L24: =J24-K24 -> -2249001 | R24: PVC | S24: =COUNTIF($R$3:R24,R24) -> 5 | T24: =C24 -> 심금STS430A 0.4*45.5 | U24: =H24 -> 3262 | V24: =I24 -> 8641038 | X24: =$X$4 -> 압출 PCM | Y24: =ROW()-6 -> 18 | Z24: {=IFERROR(INDEX($T$3:$T$373,MATCH(1,($X24=$R$3:$R$373)*($Y24=$S$3:$S$373),0))," ")} -> W60713 | AA24: {=IFERROR(INDEX($U$3:$U$373,MATCH(1,($X24=$R$3:$R$373)*($Y24=$S$3:$S$373),0))," ")} -> 0 | AB24: {=IFERROR(INDEX($V$3:$V$373,MATCH(1,($X24=$R$3:$R$373)*($Y24=$S$3:$S$373),0))," ")} -> 0 | AT24: =AT22-AT23 -> #REF!
B25: 신규업체 | C25: 0.5*37.3mm | D25: M | E25: VF34,35 | F25: ㈜ 재 영 | G25: 173.5 | H25: =원자재매입내역!AL16 -> 0 | I25: =G25*H25 -> 0 | J25: =I25 -> 0 | K25: 0 | L25: =K25-J25 -> 0 | T25: =C25 -> 0.5*37.3mm | U25: =H25 -> 0 | V25: =I25 -> 0 | X25: =$X$4 -> 압출 PCM | Y25: =ROW()-6 -> 19 | Z25: {=IFERROR(INDEX($T$3:$T$373,MATCH(1,($X25=$R$3:$R$373)*($Y25=$S$3:$S$373),0))," ")} -> W60055 | AA25: {=IFERROR(INDEX($U$3:$U$373,MATCH(1,($X25=$R$3:$R$373)*($Y25=$S$3:$S$373),0))," ")} -> 0 | AB25: {=IFERROR(INDEX($V$3:$V$373,MATCH(1,($X25=$R$3:$R$373)*($Y25=$S$3:$S$373),0))," ")} -> 0
A26: PVC | B26: 12457811 | C26: COMPOUND SD#75 BK | D26: Kg | E26: PVC(PU) | F26: 화승네트웍스 | G26: 3130 | H26: =원자재매입내역!AL18 -> 5000 | I26: =G26*H26 -> 15650000 | J26: =SUM(I26:I30) -> 57594200 | K26: 51647900 | L26: =J26-K26 -> 5946300 | R26: PVC | S26: =COUNTIF($R$3:R26,R26) -> 6 | T26: =C26 -> COMPOUND SD#75 BK | U26: =H26 -> 5000 | V26: =I26 -> 15650000 | X26: =$X$4 -> 압출 PCM | Y26: =ROW()-6 -> 20 | Z26: {=IFERROR(INDEX($T$3:$T$373,MATCH(1,($X26=$R$3:$R$373)*($Y26=$S$3:$S$373),0))," ")} -> W60433 | AA26: {=IFERROR(INDEX($U$3:$U$373,MATCH(1,($X26=$R$3:$R$373)*($Y26=$S$3:$S$373),0))," ")} -> 259 | AB26: {=IFERROR(INDEX($V$3:$V$373,MATCH(1,($X26=$R$3:$R$373)*($Y26=$S$3:$S$373),0))," ")} -> 937580 | AO26: KL HOOD(2264원) | AP26: =2264*27000 -> 61128000 | AQ26: =SUM(AP26:AP27)*1.1 -> 4.577408e+08
B27: 12457859 | C27: COMPOUND SD#75 GY | D27: Kg | E27: 루플레일 | G27: 3130 | H27: =원자재매입내역!AL19 -> 0 | I27: =G27*H27 -> 0 | R27: PVC | S27: =COUNTIF($R$3:R27,R27) -> 7 | T27: =C27 -> COMPOUND SD#75 GY | U27: =H27 -> 0 | V27: =I27 -> 0 | X27: =$X$4 -> 압출 PCM | Y27: =ROW()-6 -> 21 | Z27: {=IFERROR(INDEX($T$3:$T$373,MATCH(1,($X27=$R$3:$R$373)*($Y27=$S$3:$S$373),0))," ")} -> W60433$GT | AA27: {=IFERROR(INDEX($U$3:$U$373,MATCH(1,($X27=$R$3:$R$373)*($Y27=$S$3:$S$373),0))," ")} -> 499 | AB27: {=IFERROR(INDEX($V$3:$V$373,MATCH(1,($X27=$R$3:$R$373)*($Y27=$S$3:$S$373),0))," ")} -> 1836320 | AO27: 장유매출 | AP27: 355000000
B28: B0237040178 | C28: SX553A | D28: Kg | E28: 9BQC슬립제 | G28: 36652 | H28: =원자재매입내역!AL22 -> 500 | I28: =G28*H28 -> 18326000 | R28: 9BQC | S28: =COUNTIF($R$3:R28,R28) -> 13 | T28: =C28 -> SX553A | U28: =H28 -> 500 | V28: =I28 -> 18326000 | X28: =$X$4 -> 압출 PCM | Y28: =ROW()-6 -> 22 | Z28: {=IFERROR(INDEX($T$3:$T$373,MATCH(1,($X28=$R$3:$R$373)*($Y28=$S$3:$S$373),0))," ")} -> W60513M | AA28: {=IFERROR(INDEX($U$3:$U$373,MATCH(1,($X28=$R$3:$R$373)*($Y28=$S$3:$S$373),0))," ")} -> 15665 | AB28: {=IFERROR(INDEX($V$3:$V$373,MATCH(1,($X28=$R$3:$R$373)*($Y28=$S$3:$S$373),0))," ")} -> 53261000 | AU28: 부림텍 | AV28: 10000000
A29: WIRE | B29: B01HN00067 | C29: WIRE GLASS CORD (Ø0.4mm) | D29: M | E29: JA 구리 동선 | G29: 58 | H29: =원자재매입내역!AL27 -> 136000 | I29: =G29*H29 -> 7888000 | R29: TPE | S29: =COUNTIF($R$3:R29,R29) -> 1 | T29: =C29 -> WIRE GLASS CORD (Ø0.4mm) | U29: =H29 -> 136000 | V29: =I29 -> 7888000 | X29: =$X$4 -> 압출 PCM | Y29: =ROW()-6 -> 23 | Z29: {=IFERROR(INDEX($T$3:$T$373,MATCH(1,($X29=$R$3:$R$373)*($Y29=$S$3:$S$373),0))," ")} -> W60514 | AA29: {=IFERROR(INDEX($U$3:$U$373,MATCH(1,($X29=$R$3:$R$373)*($Y29=$S$3:$S$373),0))," ")} -> 0 | AB29: {=IFERROR(INDEX($V$3:$V$373,MATCH(1,($X29=$R$3:$R$373)*($Y29=$S$3:$S$373),0))," ")} -> 0
A30: 심금 | B30: B0155093 | C30: 46MM WIRE CARRIER(05R-159) | D30: M | E30: 편조 심금 | G30: 324 | H30: =원자재매입내역!AL28 -> 48550 | I30: =G30*H30 -> 15730200 | R30: 압출 PCM | S30: =COUNTIF($R$3:R30,R30) -> 6 | T30: =C30 -> 46MM WIRE CARRIER(05R-159) | U30: =H30 -> 48550 | V30: =I30 -> 15730200 | X30: =$X$4 -> 압출 PCM | Y30: =ROW()-6 -> 24 | Z30: {=IFERROR(INDEX($T$3:$T$373,MATCH(1,($X30=$R$3:$R$373)*($Y30=$S$3:$S$373),0))," ")} -> W60515 | AA30: {=IFERROR(INDEX($U$3:$U$373,MATCH(1,($X30=$R$3:$R$373)*($Y30=$S$3:$S$373),0))," ")} -> 1018 | AB30: {=IFERROR(INDEX($V$3:$V$373,MATCH(1,($X30=$R$3:$R$373)*($Y30=$S$3:$S$373),0))," ")} -> 3410300
A31: EPDM | B31: 1 | C31: W60712$2 | D31: Kg | E31: MCA A,B,DT S/SEAL | F31: 해동무역 삼랑진 | G31: 3510 | H31: =원자재매입내역!AL30 -> 41872 | I31: =G31*H31 -> 146970720 | J31: =SUM(I31:I46) -> 332015090 | K31: 321169980 | L31: =J31-K31 -> 10845110 | R31: 압출 PCM | S31: =COUNTIF($R$3:R31,R31) -> 7 | T31: =C31 -> W60712$2 | U31: =H31 -> 41872 | V31: =I31 -> 146970720 | X31: =$X$4 -> 압출 PCM | Y31: =ROW()-6 -> 25 | Z31: {=IFERROR(INDEX($T$3:$T$373,MATCH(1,($X31=$R$3:$R$373)*($Y31=$S$3:$S$373),0))," ")} -> W6085YU | AA31: {=IFERROR(INDEX($U$3:$U$373,MATCH(1,($X31=$R$3:$R$373)*($Y31=$S$3:$S$373),0))," ")} -> 3828 | AB31: {=IFERROR(INDEX($V$3:$V$373,MATCH(1,($X31=$R$3:$R$373)*($Y31=$S$3:$S$373),0))," ")} -> 13474560
B32: 2 | C32: W60712$2TA | D32: Kg | E32: MCA A,B,DT S/SEAL | G32: 3340 | H32: =원자재매입내역!AL31 -> 7168 | I32: =G32*H32 -> 23941120 | R32: 압출 PCM | S32: =COUNTIF($R$3:R32,R32) -> 8 | T32: =C32 -> W60712$2TA | U32: =H32 -> 7168 | V32: =I32 -> 23941120 | X32: =$X$4 -> 압출 PCM | Y32: =ROW()-6 -> 26 | Z32: {=IFERROR(INDEX($T$3:$T$373,MATCH(1,($X32=$R$3:$R$373)*($Y32=$S$3:$S$373),0))," ")} -> W60351 | AA32: {=IFERROR(INDEX($U$3:$U$373,MATCH(1,($X32=$R$3:$R$373)*($Y32=$S$3:$S$373),0))," ")} -> 0 | AB32: {=IFERROR(INDEX($V$3:$V$373,MATCH(1,($X32=$R$3:$R$373)*($Y32=$S$3:$S$373),0))," ")} -> 0
